Workbook

Sheet Title_page
A1: Significance of the Dispersion Force for Ferroelectric Switching in ZnO and Related Materials
A3: Lingyao Zhang1,2, Musen Li1,3,4, Nisha Mehta3, Carla Verdi5, Wei Ren,1,4* and Jeffrey R. Reimers1,3*
A5: 1 Physics Department, State Key Laboratory of Advanced Refractories, Materials Genome Institute, International Centre for Quantum and Molecular Structures, Shanghai University, Shanghai 200444, China
A6: 2 Department of Materials Science, University of Milan-Bicocca, Via Roberto Cozzi 55, 20125 Milan, Italy
A7: 3 University of Technology Sydney, School of Mathematical and Physical Sciences, Ultimo, New South Wales 2007, Australia.
A8: 4 Institute for Quantum Science and Technology, Shanghai Engineering Research Center for Integrated Circuits and Advanced Display Materials, Shanghai University, Shanghai 200444, China.
A9: 5 School of Mathematics and Physics, The University of Queensland, Brisbane, Queensland, 4072, Australia
A11: Contents of spreadsheets
A12: 1. Title Page
A14: 2. Summary
A15: This summarises the main results and constructs the tables and figures of the Main text.
A16: Rows 1-113: key structural and energetics properties are collected together from the individual results spreadsheets
... A46: Rows 256 Onwards: Additional RPA and RPAR calculations at PBE0 optimised geometries for Table 1 etc.

Sheet Summary
A1: structure | B1: Metal | C1: Functional | D1: filename | E1: structural properties | J1: Energy changes from C (eV/4_atom cell) | O1: Bandgap | Q1: E_MP2 | R1: diff to E_MP2 min | S1: diff sum | T1: sum ZnO+ZnMgO2 | U1: lattice vec sum abs error | V1: sum ZnO+ZnMgO2
E2: a | F2: c | G2: z(Zn-O) | H2: z(Zn/Mg-O) | I2: interplane ratio | J2: DFT | K2: HF | L2: correl | M2: MP2 | N2: MP2 corr | O2: DFT | P2: HF | Q2: B is at 0.5
A4: A | B4: Mg | C4: HSE06D3 | D4: =VLOOKUP($A4,INDIRECT("'"&$B4&"_"&$C4&"'!"&"A:Z"),COLUMN(B$1),FALSE) -> Zn_Mg_C_HSE06D3_999 | E4: =VLOOKUP($A4,INDIRECT("'"&$B4&"_"&$C4&"'!"&"A:Z"),COLUMN(D$1),FALSE) -> 3.2453 | F4: =VLOOKUP($A4,INDIRECT("'"&$B4&"_"&$C4&"'!"&"A:Z"),COLUMN(E$2),FALSE) -> 5.0937 | G4: =VLOOKUP($A4,INDIRECT("'"&$B4&"_"&$C4&"'!"&"A:Z"),COLUMN(F$2),FALSE) -> 0.61106063 | H4: =VLOOKUP($A4,INDIRECT("'"&$B4&"_"&$C4&"'!"&"A:Z"),COLUMN(G$2),FALSE) -> 0.54010539 | I4: =VLOOKUP($A4,INDIRECT("'"&$B4&"_"&$C4&"'!"&"A:Z"),COLUMN(H$2),FALSE) -> 0.505567 | J4: =VLOOKUP($A4,INDIRECT("'"&$B4&"_"&$C4&"'!"&"A:Z"),COLUMN(O$1),FALSE) -> 0.0144 | K4: =VLOOKUP($A4,INDIRECT("'"&$B4&"_"&$C4&"'!"&"A:Z"),COLUMN(P$1),FALSE) -> -0.1033 | L4: =VLOOKUP($A4,INDIRECT("'"&$B4&"_"&$C4&"'!"&"A:Z"),COLUMN(Q$1),FALSE) -> 0.0908 | M4: =VLOOKUP($A4,INDIRECT("'"&$B4&"_"&$C4&"'!"&"A:Z"),COLUMN(R$1),FALSE) -> -0.0125 | N4: =VLOOKUP($A4,INDIRECT("'"&$B4&"_"&$C4&"'!"&"A:Z"),COLUMN(Y$1),FALSE) -> 0.0019 | O4: =VLOOKUP($A4,INDIRECT("'"&$B4&"_"&$C4&"'!"&"A:Z"),COLUMN($T$1),FALSE) -> 3.598 | P4: =VLOOKUP($A4,INDIRECT("'"&$B4&"_"&$C4&"'!"&"A:Z"),COLUMN($U$1),FALSE) -> 0 | Q4: =VLOOKUP($A4,INDIRECT("'"&$B4&"_"&$C4&"'!"&"A:Z"),COLUMN($M$1),FALSE) -> -77.4478 | R4: =Q4-Q$54 -> 0.1083 | S4: =SUM(R4:R6) -> 0.303 | T4: =S4+S62 -> 0.3644 | U4: =ABS(E4-E$54)+ABS(F4-F$54) -> 0.101 | V4: =U4+U62 -> 0.1844
A5: B | B5: Mg | C5: HSE06D3 | D5: =VLOOKUP($A5,INDIRECT("'"&$B5&"_"&$C5&"'!"&"A:Z"),COLUMN(B$1),FALSE) -> Zn_Mg_C_HSE06D3_500 | E5: =VLOOKUP($A5,INDIRECT("'"&$B5&"_"&$C5&"'!"&"A:Z"),COLUMN(D$1),FALSE) -> 3.3706 | F5: =VLOOKUP($A5,INDIRECT("'"&$B5&"_"&$C5&"'!"&"A:Z"),COLUMN(E$2),FALSE) -> 4.5621 | G5: =VLOOKUP($A5,INDIRECT("'"&$B5&"_"&$C5&"'!"&"A:Z"),COLUMN(F$2),FALSE) -> 0.26982997 | H5: =VLOOKUP($A5,INDIRECT("'"&$B5&"_"&$C5&"'!"&"A:Z"),COLUMN(G$2),FALSE) -> 0.23352021 | I5: =VLOOKUP($A5,INDIRECT("'"&$B5&"_"&$C5&"'!"&"A:Z"),COLUMN(H$2),FALSE) -> 0.501947 | J5: =VLOOKUP($A5,INDIRECT("'"&$B5&"_"&$C5&"'!"&"A:Z"),COLUMN(O$1),FALSE) -> 0.0779 | K5: =VLOOKUP($A5,INDIRECT("'"&$B5&"_"&$C5&"'!"&"A:Z"),COLUMN(P$1),FALSE) -> 0.0289 | L5: =VLOOKUP($A5,INDIRECT("'"&$B5&"_"&$C5&"'!"&"A:Z"),COLUMN(Q$1),FALSE) -> 0.0274 | M5: =VLOOKUP($A5,INDIRECT("'"&$B5&"_"&$C5&"'!"&"A:Z"),COLUMN(R$1),FALSE) -> 0.0563 | N5: =VLOOKUP($A5,INDIRECT("'"&$B5&"_"&$C5&"'!"&"A:Z"),COLUMN(Y$1),FALSE) -> 0.1342 | O5: =VLOOKUP($A5,INDIRECT("'"&$B5&"_"&$C5&"'!"&"A:Z"),COLUMN(T$1),FALSE) -> 3.483 | P5: =VLOOKUP($A5,INDIRECT("'"&$B5&"_"&$C5&"'!"&"A:Z"),COLUMN(U$1),FALSE) -> 0 | Q5: {=INDIRECT("'"&$B5&"_"&$C5&"'!"&"M30")} -> -77.379 | R5: =Q5-Q$55 -> 0.1057
A6: C | B6: Mg | C6: HSE06D3 | D6: =VLOOKUP($A6,INDIRECT("'"&$B6&"_"&$C6&"'!"&"A:Z"),COLUMN(B$1),FALSE) -> Zn_Mg_C_HSE06D3_000 | E6: =VLOOKUP($A6,INDIRECT("'"&$B6&"_"&$C6&"'!"&"A:Z"),COLUMN(D$1),FALSE) -> 3.4497 | F6: =VLOOKUP($A6,INDIRECT("'"&$B6&"_"&$C6&"'!"&"A:Z"),COLUMN(E$2),FALSE) -> 4.2409 | G6: =VLOOKUP($A6,INDIRECT("'"&$B6&"_"&$C6&"'!"&"A:Z"),COLUMN(F$2),FALSE) -> 0 | H6: =VLOOKUP($A6,INDIRECT("'"&$B6&"_"&$C6&"'!"&"A:Z"),COLUMN(G$2),FALSE) -> 0 | I6: =VLOOKUP($A6,INDIRECT("'"&$B6&"_"&$C6&"'!"&"A:Z"),COLUMN(H$2),FALSE) -> 0.5 | J6: =VLOOKUP($A6,INDIRECT("'"&$B6&"_"&$C6&"'!"&"A:Z"),COLUMN(O$1),FALSE) -> 0 | K6: =VLOOKUP($A6,INDIRECT("'"&$B6&"_"&$C6&"'!"&"A:Z"),COLUMN(P$1),FALSE) -> 0 | L6: =VLOOKUP($A6,INDIRECT("'"&$B6&"_"&$C6&"'!"&"A:Z"),COLUMN(Q$1),FALSE) -> 0 | M6: =VLOOKUP($A6,INDIRECT("'"&$B6&"_"&$C6&"'!"&"A:Z"),COLUMN(R$1),FALSE) -> 0 | N6: =VLOOKUP($A6,INDIRECT("'"&$B6&"_"&$C6&"'!"&"A:Z"),COLUMN(Y$1),FALSE) -> 0 | O6: =VLOOKUP($A6,INDIRECT("'"&$B6&"_"&$C6&"'!"&"A:Z"),COLUMN(T$1),FALSE) -> 3.045 | P6: =VLOOKUP($A6,INDIRECT("'"&$B6&"_"&$C6&"'!"&"A:Z"),COLUMN(U$1),FALSE) -> 0 | Q6: =VLOOKUP($A6,INDIRECT("'"&$B6&"_"&$C6&"'!"&"A:Z"),COLUMN(M$1),FALSE) -> -77.4353 | R6: =Q6-Q$56 -> 0.089
A7: V | B7: Mg | C7: HSE06D3 | D7: =VLOOKUP($A7,INDIRECT("'"&$B7&"_"&$C7&"'!"&"A:Z"),COLUMN(B$1),FALSE) -> Zn_Mg_C_HSE06D3_ver | E7: =VLOOKUP($A7,INDIRECT("'"&$B7&"_"&$C7&"'!"&"A:Z"),COLUMN(D$1),FALSE) -> 3.2453 | F7: =VLOOKUP($A7,INDIRECT("'"&$B7&"_"&$C7&"'!"&"A:Z"),COLUMN(E$2),FALSE) -> 5.0937 | G7: =VLOOKUP($A7,INDIRECT("'"&$B7&"_"&$C7&"'!"&"A:Z"),COLUMN(F$2),FALSE) -> 0 | H7: =VLOOKUP($A7,INDIRECT("'"&$B7&"_"&$C7&"'!"&"A:Z"),COLUMN(G$2),FALSE) -> 0 | I7: =VLOOKUP($A7,INDIRECT("'"&$B7&"_"&$C7&"'!"&"A:Z"),COLUMN(H$2),FALSE) -> 0.5 | J7: =VLOOKUP($A7,INDIRECT("'"&$B7&"_"&$C7&"'!"&"A:Z"),COLUMN(O$1),FALSE) -> 0.6043 | K7: =VLOOKUP($A7,INDIRECT("'"&$B7&"_"&$C7&"'!"&"A:Z"),COLUMN(P$1),FALSE) -> 58.5165 | L7: =VLOOKUP($A7,INDIRECT("'"&$B7&"_"&$C7&"'!"&"A:Z"),COLUMN(Q$1),FALSE) -> 18.9188 | M7: =VLOOKUP($A7,INDIRECT("'"&$B7&"_"&$C7&"'!"&"A:Z"),COLUMN(R$1),FALSE) -> 77.4353 | N7: =VLOOKUP($A7,INDIRECT("'"&$B7&"_"&$C7&"'!"&"A:Z"),COLUMN(Y$1),FALSE) -> 78.0396 | O7: =VLOOKUP($A7,INDIRECT("'"&$B7&"_"&$C7&"'!"&"A:Z"),COLUMN(T$1),FALSE) -> 3.426 | P7: =VLOOKUP($A7,INDIRECT("'"&$B7&"_"&$C7&"'!"&"A:Z"),COLUMN(U$1),FALSE) -> 0 | Q7: =VLOOKUP($A7,INDIRECT("'"&$B7&"_"&$C7&"'!"&"A:Z"),COLUMN(M$1),FALSE) -> 0
I8: B-A | J8: =J5-J4 -> 0.0635 | K8: =K5-K4 -> 0.1322 | L8: =L5-L4 -> -0.0634 | M8: =M5-M4 -> 0.0688 | N8: =N5-N4 -> 0.1323
A9: A | B9: Mg | C9: HSE06 | D9: =VLOOKUP($A9,INDIRECT("'"&$B9&"_"&$C9&"'!"&"A:Z"),COLUMN(B$1),FALSE) -> Zn_Mg_C_HSE06_999 | E9: =VLOOKUP($A9,INDIRECT("'"&$B9&"_"&$C9&"'!"&"A:Z"),COLUMN(D$1),FALSE) -> 3.2687 | F9: =VLOOKUP($A9,INDIRECT("'"&$B9&"_"&$C9&"'!"&"A:Z"),COLUMN(E$2),FALSE) -> 5.1516 | G9: =VLOOKUP($A9,INDIRECT("'"&$B9&"_"&$C9&"'!"&"A:Z"),COLUMN(F$2),FALSE) -> 0.62337966 | H9: =VLOOKUP($A9,INDIRECT("'"&$B9&"_"&$C9&"'!"&"A:Z"),COLUMN(G$2),FALSE) -> 0.55455944 | I9: =VLOOKUP($A9,INDIRECT("'"&$B9&"_"&$C9&"'!"&"A:Z"),COLUMN(H$2),FALSE) -> 0.505551 | J9: =VLOOKUP($A9,INDIRECT("'"&$B9&"_"&$C9&"'!"&"A:Z"),COLUMN(O$1),FALSE) -> -0.0541 | K9: =VLOOKUP($A9,INDIRECT("'"&$B9&"_"&$C9&"'!"&"A:Z"),COLUMN(P$1),FALSE) -> -0.1094 | L9: =VLOOKUP($A9,INDIRECT("'"&$B9&"_"&$C9&"'!"&"A:Z"),COLUMN(Q$1),FALSE) -> 0.0901 | M9: =VLOOKUP($A9,INDIRECT("'"&$B9&"_"&$C9&"'!"&"A:Z"),COLUMN(R$1),FALSE) -> -0.0193 | N9: =VLOOKUP($A9,INDIRECT("'"&$B9&"_"&$C9&"'!"&"A:Z"),COLUMN(Y$1),FALSE) -> -0.0734 | O9: =VLOOKUP($A9,INDIRECT("'"&$B9&"_"&$C9&"'!"&"A:Z"),COLUMN($T$1),FALSE) -> 3.512 | P9: =VLOOKUP($A9,INDIRECT("'"&$B9&"_"&$C9&"'!"&"A:Z"),COLUMN($U$1),FALSE) -> 0 | Q9: =VLOOKUP($A9,INDIRECT("'"&$B9&"_"&$C9&"'!"&"A:Z"),COLUMN($M$1),FALSE) -> -77.4822 | R9: =Q9-Q$54 -> 0.0739 | S9: =SUM(R9:R11) -> 0.1925 | T9: =S9+S67 -> 0.1988 | U9: =ABS(E9-E$54)+ABS(F9-F$54) -> 0.0531 | V9: =U9+U67 -> 0.1311
A10: B | B10: Mg | C10: HSE06 | D10: =VLOOKUP($A10,INDIRECT("'"&$B10&"_"&$C10&"'!"&"A:Z"),COLUMN(B$1),FALSE) -> Zn_Mg_C_HSE06_438 | E10: =VLOOKUP($A10,INDIRECT("'"&$B10&"_"&$C10&"'!"&"A:Z"),COLUMN(D$1),FALSE) -> 3.4051 | F10: =VLOOKUP($A10,INDIRECT("'"&$B10&"_"&$C10&"'!"&"A:Z"),COLUMN(E$2),FALSE) -> 4.5743 | G10: =VLOOKUP($A10,INDIRECT("'"&$B10&"_"&$C10&"'!"&"A:Z"),COLUMN(F$2),FALSE) -> 0.24650903 | H10: =VLOOKUP($A10,INDIRECT("'"&$B10&"_"&$C10&"'!"&"A:Z"),COLUMN(G$2),FALSE) -> 0.21234815 | I10: =VLOOKUP($A10,INDIRECT("'"&$B10&"_"&$C10&"'!"&"A:Z"),COLUMN(H$2),FALSE) -> 0.503378 | J10: =VLOOKUP($A10,INDIRECT("'"&$B10&"_"&$C10&"'!"&"A:Z"),COLUMN(O$1),FALSE) -> 0.0484 | K10: =VLOOKUP($A10,INDIRECT("'"&$B10&"_"&$C10&"'!"&"A:Z"),COLUMN(P$1),FALSE) -> 0.0265 | L10: =VLOOKUP($A10,INDIRECT("'"&$B10&"_"&$C10&"'!"&"A:Z"),COLUMN(Q$1),FALSE) -> 0.0154 | M10: =VLOOKUP($A10,INDIRECT("'"&$B10&"_"&$C10&"'!"&"A:Z"),COLUMN(R$1),FALSE) -> 0.0419 | N10: =VLOOKUP($A10,INDIRECT("'"&$B10&"_"&$C10&"'!"&"A:Z"),COLUMN(Y$1),FALSE) -> 0.0903 | O10: =VLOOKUP($A10,INDIRECT("'"&$B10&"_"&$C10&"'!"&"A:Z"),COLUMN(T$1),FALSE) -> 3.337 | P10: =VLOOKUP($A10,INDIRECT("'"&$B10&"_"&$C10&"'!"&"A:Z"),COLUMN(U$1),FALSE) -> 0 | Q10: {=INDIRECT("'"&$B10&"_"&$C10&"'!"&"M30")} -> -77.4275 | R10: =Q10-Q$55 -> 0.0572
A11: C | B11: Mg | C11: HSE06 | D11: =VLOOKUP($A11,INDIRECT("'"&$B11&"_"&$C11&"'!"&"A:Z"),COLUMN(B$1),FALSE) -> Zn_Mg_C_HSE06_000 | E11: =VLOOKUP($A11,INDIRECT("'"&$B11&"_"&$C11&"'!"&"A:Z"),COLUMN(D$1),FALSE) -> 3.479 | F11: =VLOOKUP($A11,INDIRECT("'"&$B11&"_"&$C11&"'!"&"A:Z"),COLUMN(E$2),FALSE) -> 4.2828 | G11: =VLOOKUP($A11,INDIRECT("'"&$B11&"_"&$C11&"'!"&"A:Z"),COLUMN(F$2),FALSE) -> 0 | H11: =VLOOKUP($A11,INDIRECT("'"&$B11&"_"&$C11&"'!"&"A:Z"),COLUMN(G$2),FALSE) -> 0 | I11: =VLOOKUP($A11,INDIRECT("'"&$B11&"_"&$C11&"'!"&"A:Z"),COLUMN(H$2),FALSE) -> 0.5 | J11: =VLOOKUP($A11,INDIRECT("'"&$B11&"_"&$C11&"'!"&"A:Z"),COLUMN(O$1),FALSE) -> 0 | K11: =VLOOKUP($A11,INDIRECT("'"&$B11&"_"&$C11&"'!"&"A:Z"),COLUMN(P$1),FALSE) -> 0 | L11: =VLOOKUP($A11,INDIRECT("'"&$B11&"_"&$C11&"'!"&"A:Z"),COLUMN(Q$1),FALSE) -> 0 | M11: =VLOOKUP($A11,INDIRECT("'"&$B11&"_"&$C11&"'!"&"A:Z"),COLUMN(R$1),FALSE) -> 0 | N11: =VLOOKUP($A11,INDIRECT("'"&$B11&"_"&$C11&"'!"&"A:Z"),COLUMN(Y$1),FALSE) -> 0 | O11: =VLOOKUP($A11,INDIRECT("'"&$B11&"_"&$C11&"'!"&"A:Z"),COLUMN(T$1),FALSE) -> 2.96 | P11: =VLOOKUP($A11,INDIRECT("'"&$B11&"_"&$C11&"'!"&"A:Z"),COLUMN(U$1),FALSE) -> 0 | Q11: =VLOOKUP($A11,INDIRECT("'"&$B11&"_"&$C11&"'!"&"A:Z"),COLUMN(M$1),FALSE) -> -77.4629 | R11: =Q11-Q$56 -> 0.0614
A12: V | B12: Mg | C12: HSE06 | D12: =VLOOKUP($A12,INDIRECT("'"&$B12&"_"&$C12&"'!"&"A:Z"),COLUMN(B$1),FALSE) -> Zn_Mg_C_HSE06_ver | E12: =VLOOKUP($A12,INDIRECT("'"&$B12&"_"&$C12&"'!"&"A:Z"),COLUMN(D$1),FALSE) -> 3.2687 | F12: =VLOOKUP($A12,INDIRECT("'"&$B12&"_"&$C12&"'!"&"A:Z"),COLUMN(E$2),FALSE) -> 5.1516 | G12: =VLOOKUP($A12,INDIRECT("'"&$B12&"_"&$C12&"'!"&"A:Z"),COLUMN(F$2),FALSE) -> 0 | H12: =VLOOKUP($A12,INDIRECT("'"&$B12&"_"&$C12&"'!"&"A:Z"),COLUMN(G$2),FALSE) -> 0 | I12: =VLOOKUP($A12,INDIRECT("'"&$B12&"_"&$C12&"'!"&"A:Z"),COLUMN(H$2),FALSE) -> 0.5 | J12: =VLOOKUP($A12,INDIRECT("'"&$B12&"_"&$C12&"'!"&"A:Z"),COLUMN(O$1),FALSE) -> 0.5128 | K12: =VLOOKUP($A12,INDIRECT("'"&$B12&"_"&$C12&"'!"&"A:Z"),COLUMN(P$1),FALSE) -> 58.5263 | L12: =VLOOKUP($A12,INDIRECT("'"&$B12&"_"&$C12&"'!"&"A:Z"),COLUMN(Q$1),FALSE) -> 18.9366 | M12: =VLOOKUP($A12,INDIRECT("'"&$B12&"_"&$C12&"'!"&"A:Z"),COLUMN(R$1),FALSE) -> 77.4629 | N12: =VLOOKUP($A12,INDIRECT("'"&$B12&"_"&$C12&"'!"&"A:Z"),COLUMN(Y$1),FALSE) -> 77.9757 | O12: =VLOOKUP($A12,INDIRECT("'"&$B12&"_"&$C12&"'!"&"A:Z"),COLUMN(T$1),FALSE) -> 3.362 | P12: =VLOOKUP($A12,INDIRECT("'"&$B12&"_"&$C12&"'!"&"A:Z"),COLUMN(U$1),FALSE) -> 0 | Q12: =VLOOKUP($A12,INDIRECT("'"&$B12&"_"&$C12&"'!"&"A:Z"),COLUMN(M$1),FALSE) -> 0
I13: B-A | J13: =J10-J9 -> 0.1025 | K13: =K10-K9 -> 0.1359 | L13: =L10-L9 -> -0.0747 | M13: =M10-M9 -> 0.0612 | N13: =N10-N9 -> 0.1637
A14: A | B14: Mg | C14: PBE0D3 | D14: =VLOOKUP($A14,INDIRECT("'"&$B14&"_"&$C14&"'!"&"A:Z"),COLUMN(B$1),FALSE) -> Zn_Mg_C_PBE0D3_999 | E14: =VLOOKUP($A14,INDIRECT("'"&$B14&"_"&$C14&"'!"&"A:Z"),COLUMN(D$1),FALSE) -> 3.2452 | F14: =VLOOKUP($A14,INDIRECT("'"&$B14&"_"&$C14&"'!"&"A:Z"),COLUMN(E$2),FALSE) -> 5.0967 | G14: =VLOOKUP($A14,INDIRECT("'"&$B14&"_"&$C14&"'!"&"A:Z"),COLUMN(F$2),FALSE) -> 0.61179258 | H14: =VLOOKUP($A14,INDIRECT("'"&$B14&"_"&$C14&"'!"&"A:Z"),COLUMN(G$2),FALSE) -> 0.54159063 | I14: =VLOOKUP($A14,INDIRECT("'"&$B14&"_"&$C14&"'!"&"A:Z"),COLUMN(H$2),FALSE) -> 0.50556 | J14: =VLOOKUP($A14,INDIRECT("'"&$B14&"_"&$C14&"'!"&"A:Z"),COLUMN(O$1),FALSE) -> 0.0052 | K14: =VLOOKUP($A14,INDIRECT("'"&$B14&"_"&$C14&"'!"&"A:Z"),COLUMN(P$1),FALSE) -> -0.1024 | L14: =VLOOKUP($A14,INDIRECT("'"&$B14&"_"&$C14&"'!"&"A:Z"),COLUMN(Q$1),FALSE) -> 0.0947 | M14: =VLOOKUP($A14,INDIRECT("'"&$B14&"_"&$C14&"'!"&"A:Z"),COLUMN(R$1),FALSE) -> -0.0077 | N14: =VLOOKUP($A14,INDIRECT("'"&$B14&"_"&$C14&"'!"&"A:Z"),COLUMN(Y$1),FALSE) -> -0.0025 | O14: =VLOOKUP($A14,INDIRECT("'"&$B14&"_"&$C14&"'!"&"A:Z"),COLUMN($T$1),FALSE) -> 4.295 | P14: =VLOOKUP($A14,INDIRECT("'"&$B14&"_"&$C14&"'!"&"A:Z"),COLUMN($U$1),FALSE) -> 0 | Q14: =VLOOKUP($A14,INDIRECT("'"&$B14&"_"&$C14&"'!"&"A:Z"),COLUMN($M$1),FALSE) -> -77.5032 | R14: =Q14-Q$54 -> 0.0529 | S14: =SUM(R14:R16) -> 0.128 | T14: =S14+S72 -> 0.1896 | U14: =ABS(E14-E$54)+ABS(F14-F$54) -> 0.0981 | V14: =U14+U72 -> 0.1738
A15: B | B15: Mg | C15: PBE0D3 | D15: =VLOOKUP($A15,INDIRECT("'"&$B15&"_"&$C15&"'!"&"A:Z"),COLUMN(B$1),FALSE) -> Zn_Mg_C_PBE0D3_500 | E15: =VLOOKUP($A15,INDIRECT("'"&$B15&"_"&$C15&"'!"&"A:Z"),COLUMN(D$1),FALSE) -> 3.3698 | F15: =VLOOKUP($A15,INDIRECT("'"&$B15&"_"&$C15&"'!"&"A:Z"),COLUMN(E$2),FALSE) -> 4.5701 | G15: =VLOOKUP($A15,INDIRECT("'"&$B15&"_"&$C15&"'!"&"A:Z"),COLUMN(F$2),FALSE) -> 0.2724785 | H15: =VLOOKUP($A15,INDIRECT("'"&$B15&"_"&$C15&"'!"&"A:Z"),COLUMN(G$2),FALSE) -> 0.23442328 | I15: =VLOOKUP($A15,INDIRECT("'"&$B15&"_"&$C15&"'!"&"A:Z"),COLUMN(H$2),FALSE) -> 0.502384 | J15: =VLOOKUP($A15,INDIRECT("'"&$B15&"_"&$C15&"'!"&"A:Z"),COLUMN(O$1),FALSE) -> 0.0735 | K15: =VLOOKUP($A15,INDIRECT("'"&$B15&"_"&$C15&"'!"&"A:Z"),COLUMN(P$1),FALSE) -> 0.0282 | L15: =VLOOKUP($A15,INDIRECT("'"&$B15&"_"&$C15&"'!"&"A:Z"),COLUMN(Q$1),FALSE) -> 0.0289 | M15: =VLOOKUP($A15,INDIRECT("'"&$B15&"_"&$C15&"'!"&"A:Z"),COLUMN(R$1),FALSE) -> 0.0571 | N15: =VLOOKUP($A15,INDIRECT("'"&$B15&"_"&$C15&"'!"&"A:Z"),COLUMN(Y$1),FALSE) -> 0.1306 | O15: =VLOOKUP($A15,INDIRECT("'"&$B15&"_"&$C15&"'!"&"A:Z"),COLUMN(T$1),FALSE) -> 4.192 | P15: =VLOOKUP($A15,INDIRECT("'"&$B15&"_"&$C15&"'!"&"A:Z"),COLUMN(U$1),FALSE) -> 0 | Q15: {=INDIRECT("'"&$B15&"_"&$C15&"'!"&"M30")} -> -77.4384 | R15: =Q15-Q$55 -> 0.0463
A16: C | B16: Mg | C16: PBE0D3 | D16: =VLOOKUP($A16,INDIRECT("'"&$B16&"_"&$C16&"'!"&"A:Z"),COLUMN(B$1),FALSE) -> Zn_Mg_C_PBE0D3_000 | E16: =VLOOKUP($A16,INDIRECT("'"&$B16&"_"&$C16&"'!"&"A:Z"),COLUMN(D$1),FALSE) -> 3.4494 | F16: =VLOOKUP($A16,INDIRECT("'"&$B16&"_"&$C16&"'!"&"A:Z"),COLUMN(E$2),FALSE) -> 4.2458 | G16: =VLOOKUP($A16,INDIRECT("'"&$B16&"_"&$C16&"'!"&"A:Z"),COLUMN(F$2),FALSE) -> 0 | H16: =VLOOKUP($A16,INDIRECT("'"&$B16&"_"&$C16&"'!"&"A:Z"),COLUMN(G$2),FALSE) -> 0 | I16: =VLOOKUP($A16,INDIRECT("'"&$B16&"_"&$C16&"'!"&"A:Z"),COLUMN(H$2),FALSE) -> 0.5 | J16: =VLOOKUP($A16,INDIRECT("'"&$B16&"_"&$C16&"'!"&"A:Z"),COLUMN(O$1),FALSE) -> 0 | K16: =VLOOKUP($A16,INDIRECT("'"&$B16&"_"&$C16&"'!"&"A:Z"),COLUMN(P$1),FALSE) -> 0 | L16: =VLOOKUP($A16,INDIRECT("'"&$B16&"_"&$C16&"'!"&"A:Z"),COLUMN(Q$1),FALSE) -> 0 | M16: =VLOOKUP($A16,INDIRECT("'"&$B16&"_"&$C16&"'!"&"A:Z"),COLUMN(R$1),FALSE) -> 0 | N16: =VLOOKUP($A16,INDIRECT("'"&$B16&"_"&$C16&"'!"&"A:Z"),COLUMN(Y$1),FALSE) -> 0 | O16: =VLOOKUP($A16,INDIRECT("'"&$B16&"_"&$C16&"'!"&"A:Z"),COLUMN(T$1),FALSE) -> 3.745 | P16: =VLOOKUP($A16,INDIRECT("'"&$B16&"_"&$C16&"'!"&"A:Z"),COLUMN(U$1),FALSE) -> 0 | Q16: =VLOOKUP($A16,INDIRECT("'"&$B16&"_"&$C16&"'!"&"A:Z"),COLUMN(M$1),FALSE) -> -77.4955 | R16: =Q16-Q$56 -> 0.0288
A17: V | B17: Mg | C17: PBE0D3 | D17: =VLOOKUP($A17,INDIRECT("'"&$B17&"_"&$C17&"'!"&"A:Z"),COLUMN(B$1),FALSE) -> Zn_Mg_C_PBE0D3_ver | E17: =VLOOKUP($A17,INDIRECT("'"&$B17&"_"&$C17&"'!"&"A:Z"),COLUMN(D$1),FALSE) -> 3.2452 | F17: =VLOOKUP($A17,INDIRECT("'"&$B17&"_"&$C17&"'!"&"A:Z"),COLUMN(E$2),FALSE) -> 5.0967 | G17: =VLOOKUP($A17,INDIRECT("'"&$B17&"_"&$C17&"'!"&"A:Z"),COLUMN(F$2),FALSE) -> 0 | H17: =VLOOKUP($A17,INDIRECT("'"&$B17&"_"&$C17&"'!"&"A:Z"),COLUMN(G$2),FALSE) -> 0 | I17: =VLOOKUP($A17,INDIRECT("'"&$B17&"_"&$C17&"'!"&"A:Z"),COLUMN(H$2),FALSE) -> 0.5 | J17: =VLOOKUP($A17,INDIRECT("'"&$B17&"_"&$C17&"'!"&"A:Z"),COLUMN(O$1),FALSE) -> 0.5971 | K17: =VLOOKUP($A17,INDIRECT("'"&$B17&"_"&$C17&"'!"&"A:Z"),COLUMN(P$1),FALSE) -> 58.5176 | L17: =VLOOKUP($A17,INDIRECT("'"&$B17&"_"&$C17&"'!"&"A:Z"),COLUMN(Q$1),FALSE) -> 18.9779 | M17: =VLOOKUP($A17,INDIRECT("'"&$B17&"_"&$C17&"'!"&"A:Z"),COLUMN(R$1),FALSE) -> 77.4955 | N17: =VLOOKUP($A17,INDIRECT("'"&$B17&"_"&$C17&"'!"&"A:Z"),COLUMN(Y$1),FALSE) -> 78.0926 | O17: =VLOOKUP($A17,INDIRECT("'"&$B17&"_"&$C17&"'!"&"A:Z"),COLUMN(T$1),FALSE) -> 4.125 | P17: =VLOOKUP($A17,INDIRECT("'"&$B17&"_"&$C17&"'!"&"A:Z"),COLUMN(U$1),FALSE) -> 0 | Q17: =VLOOKUP($A17,INDIRECT("'"&$B17&"_"&$C17&"'!"&"A:Z"),COLUMN(M$1),FALSE) -> 0
I18: B-A | J18: =J15-J14 -> 0.0683 | K18: =K15-K14 -> 0.1306 | L18: =L15-L14 -> -0.0658 | M18: =M15-M14 -> 0.0648 | N18: =N15-N14 -> 0.1331
A19: A | B19: Mg | C19: PBE0 | D19: =VLOOKUP($A19,INDIRECT("'"&$B19&"_"&$C19&"'!"&"A:Z"),COLUMN(B$1),FALSE) -> Zn_Mg_C_PBE0_999 | E19: =VLOOKUP($A19,INDIRECT("'"&$B19&"_"&$C19&"'!"&"A:Z"),COLUMN(D$1),FALSE) -> 3.2669 | F19: =VLOOKUP($A19,INDIRECT("'"&$B19&"_"&$C19&"'!"&"A:Z"),COLUMN(E$2),FALSE) -> 5.1502 | G19: =VLOOKUP($A19,INDIRECT("'"&$B19&"_"&$C19&"'!"&"A:Z"),COLUMN(F$2),FALSE) -> 0.62341111 | H19: =VLOOKUP($A19,INDIRECT("'"&$B19&"_"&$C19&"'!"&"A:Z"),COLUMN(G$2),FALSE) -> 0.55517611 | I19: =VLOOKUP($A19,INDIRECT("'"&$B19&"_"&$C19&"'!"&"A:Z"),COLUMN(H$2),FALSE) -> 0.50555 | J19: =VLOOKUP($A19,INDIRECT("'"&$B19&"_"&$C19&"'!"&"A:Z"),COLUMN(O$1),FALSE) -> -0.054 | K19: =VLOOKUP($A19,INDIRECT("'"&$B19&"_"&$C19&"'!"&"A:Z"),COLUMN(P$1),FALSE) -> -0.1094 | L19: =VLOOKUP($A19,INDIRECT("'"&$B19&"_"&$C19&"'!"&"A:Z"),COLUMN(Q$1),FALSE) -> 0.0937 | M19: =VLOOKUP($A19,INDIRECT("'"&$B19&"_"&$C19&"'!"&"A:Z"),COLUMN(R$1),FALSE) -> -0.0157 | N19: =VLOOKUP($A19,INDIRECT("'"&$B19&"_"&$C19&"'!"&"A:Z"),COLUMN(Y$1),FALSE) -> -0.0614 | O19: =VLOOKUP($A19,INDIRECT("'"&$B19&"_"&$C19&"'!"&"A:Z"),COLUMN($T$1),FALSE) -> 4.213 | P19: =VLOOKUP($A19,INDIRECT("'"&$B19&"_"&$C19&"'!"&"A:Z"),COLUMN($U$1),FALSE) -> 12.422 | Q19: =VLOOKUP($A19,INDIRECT("'"&$B19&"_"&$C19&"'!"&"A:Z"),COLUMN($M$1),FALSE) -> -77.5353 | R19: =Q19-Q$54 -> 0.0208 | S19: =SUM(R19:R21) -> 0.0255 | T19: =S19+S77 -> 0.0271 | U19: =ABS(E19-E$54)+ABS(F19-F$54) -> 0.0527 | V19: =U19+U77 -> 0.1345
A20: B | B20: Mg | C20: PBE0 | D20: =VLOOKUP($A20,INDIRECT("'"&$B20&"_"&$C20&"'!"&"A:Z"),COLUMN(B$1),FALSE) -> Zn_Mg_C_PBE0_438 | E20: =VLOOKUP($A20,INDIRECT("'"&$B20&"_"&$C20&"'!"&"A:Z"),COLUMN(D$1),FALSE) -> 3.4032 | F20: =VLOOKUP($A20,INDIRECT("'"&$B20&"_"&$C20&"'!"&"A:Z"),COLUMN(E$2),FALSE) -> 4.5756 | G20: =VLOOKUP($A20,INDIRECT("'"&$B20&"_"&$C20&"'!"&"A:Z"),COLUMN(F$2),FALSE) -> 0.24738439 | H20: =VLOOKUP($A20,INDIRECT("'"&$B20&"_"&$C20&"'!"&"A:Z"),COLUMN(G$2),FALSE) -> 0.21312687 | I20: =VLOOKUP($A20,INDIRECT("'"&$B20&"_"&$C20&"'!"&"A:Z"),COLUMN(H$2),FALSE) -> 0.503537 | J20: =VLOOKUP($A20,INDIRECT("'"&$B20&"_"&$C20&"'!"&"A:Z"),COLUMN(O$1),FALSE) -> 0.0478 | K20: =VLOOKUP($A20,INDIRECT("'"&$B20&"_"&$C20&"'!"&"A:Z"),COLUMN(P$1),FALSE) -> 0.0275 | L20: =VLOOKUP($A20,INDIRECT("'"&$B20&"_"&$C20&"'!"&"A:Z"),COLUMN(Q$1),FALSE) -> 0.0192 | M20: =VLOOKUP($A20,INDIRECT("'"&$B20&"_"&$C20&"'!"&"A:Z"),COLUMN(R$1),FALSE) -> 0.0467 | N20: =VLOOKUP($A20,INDIRECT("'"&$B20&"_"&$C20&"'!"&"A:Z"),COLUMN(Y$1),FALSE) -> 0.0267 | O20: =VLOOKUP($A20,INDIRECT("'"&$B20&"_"&$C20&"'!"&"A:Z"),COLUMN(T$1),FALSE) -> 4.043 | P20: =VLOOKUP($A20,INDIRECT("'"&$B20&"_"&$C20&"'!"&"A:Z"),COLUMN(U$1),FALSE) -> 12.275 | Q20: {=INDIRECT("'"&$B20&"_"&$C20&"'!"&"M30")} -> -77.4847 | R20: =Q20-Q$55 -> 0
A21: C | B21: Mg | C21: PBE0 | D21: =VLOOKUP($A21,INDIRECT("'"&$B21&"_"&$C21&"'!"&"A:Z"),COLUMN(B$1),FALSE) -> Zn_Mg_C_PBE0_000 | E21: =VLOOKUP($A21,INDIRECT("'"&$B21&"_"&$C21&"'!"&"A:Z"),COLUMN(D$1),FALSE) -> 3.4771 | F21: =VLOOKUP($A21,INDIRECT("'"&$B21&"_"&$C21&"'!"&"A:Z"),COLUMN(E$2),FALSE) -> 4.2837 | G21: =VLOOKUP($A21,INDIRECT("'"&$B21&"_"&$C21&"'!"&"A:Z"),COLUMN(F$2),FALSE) -> 0 | H21: =VLOOKUP($A21,INDIRECT("'"&$B21&"_"&$C21&"'!"&"A:Z"),COLUMN(G$2),FALSE) -> 0 | I21: =VLOOKUP($A21,INDIRECT("'"&$B21&"_"&$C21&"'!"&"A:Z"),COLUMN(H$2),FALSE) -> 0.5 | J21: =VLOOKUP($A21,INDIRECT("'"&$B21&"_"&$C21&"'!"&"A:Z"),COLUMN(O$1),FALSE) -> 0 | K21: =VLOOKUP($A21,INDIRECT("'"&$B21&"_"&$C21&"'!"&"A:Z"),COLUMN(P$1),FALSE) -> 0 | L21: =VLOOKUP($A21,INDIRECT("'"&$B21&"_"&$C21&"'!"&"A:Z"),COLUMN(Q$1),FALSE) -> 0 | M21: =VLOOKUP($A21,INDIRECT("'"&$B21&"_"&$C21&"'!"&"A:Z"),COLUMN(R$1),FALSE) -> 0 | N21: =VLOOKUP($A21,INDIRECT("'"&$B21&"_"&$C21&"'!"&"A:Z"),COLUMN(Y$1),FALSE) -> 0 | O21: =VLOOKUP($A21,INDIRECT("'"&$B21&"_"&$C21&"'!"&"A:Z"),COLUMN(T$1),FALSE) -> 3.663 | P21: =VLOOKUP($A21,INDIRECT("'"&$B21&"_"&$C21&"'!"&"A:Z"),COLUMN(U$1),FALSE) -> 11.848 | Q21: =VLOOKUP($A21,INDIRECT("'"&$B21&"_"&$C21&"'!"&"A:Z"),COLUMN(M$1),FALSE) -> -77.5196 | R21: =Q21-Q$56 -> 0.0047
A22: V | B22: Mg | C22: PBE0 | D22: =VLOOKUP($A22,INDIRECT("'"&$B22&"_"&$C22&"'!"&"A:Z"),COLUMN(B$1),FALSE) -> Zn_Mg_C_PBE0_ver | E22: =VLOOKUP($A22,INDIRECT("'"&$B22&"_"&$C22&"'!"&"A:Z"),COLUMN(D$1),FALSE) -> 3.267 | F22: =VLOOKUP($A22,INDIRECT("'"&$B22&"_"&$C22&"'!"&"A:Z"),COLUMN(E$2),FALSE) -> 5.1502 | G22: =VLOOKUP($A22,INDIRECT("'"&$B22&"_"&$C22&"'!"&"A:Z"),COLUMN(F$2),FALSE) -> 0 | H22: =VLOOKUP($A22,INDIRECT("'"&$B22&"_"&$C22&"'!"&"A:Z"),COLUMN(G$2),FALSE) -> 0 | I22: =VLOOKUP($A22,INDIRECT("'"&$B22&"_"&$C22&"'!"&"A:Z"),COLUMN(H$2),FALSE) -> 0.5 | J22: =VLOOKUP($A22,INDIRECT("'"&$B22&"_"&$C22&"'!"&"A:Z"),COLUMN(O$1),FALSE) -> 0.5153 | K22: =VLOOKUP($A22,INDIRECT("'"&$B22&"_"&$C22&"'!"&"A:Z"),COLUMN(P$1),FALSE) -> 58.5259 | L22: =VLOOKUP($A22,INDIRECT("'"&$B22&"_"&$C22&"'!"&"A:Z"),COLUMN(Q$1),FALSE) -> 18.9937 | M22: =VLOOKUP($A22,INDIRECT("'"&$B22&"_"&$C22&"'!"&"A:Z"),COLUMN(R$1),FALSE) -> 77.5196 | N22: =VLOOKUP($A22,INDIRECT("'"&$B22&"_"&$C22&"'!"&"A:Z"),COLUMN(Y$1),FALSE) -> 77.4743 | O22: =VLOOKUP($A22,INDIRECT("'"&$B22&"_"&$C22&"'!"&"A:Z"),COLUMN(T$1),FALSE) -> 4.063 | P22: =VLOOKUP($A22,INDIRECT("'"&$B22&"_"&$C22&"'!"&"A:Z"),COLUMN(U$1),FALSE) -> 12.416 | Q22: =VLOOKUP($A22,INDIRECT("'"&$B22&"_"&$C22&"'!"&"A:Z"),COLUMN(M$1),FALSE) -> 0
I23: B-A | J23: =J20-J19 -> 0.1018 | K23: =K20-K19 -> 0.1369 | L23: =L20-L19 -> -0.0745 | M23: =M20-M19 -> 0.0624 | N23: =N20-N19 -> 0.0881
A24: A | B24: Mg | C24: PBESolD3 | D24: =VLOOKUP($A24,INDIRECT("'"&$B24&"_"&$C24&"'!"&"A:Z"),COLUMN(B$1),FALSE) -> Zn_Mg_C_PBESolD3_999 | E24: =VLOOKUP($A24,INDIRECT("'"&$B24&"_"&$C24&"'!"&"A:Z"),COLUMN(D$1),FALSE) -> 3.2513 | F24: =VLOOKUP($A24,INDIRECT("'"&$B24&"_"&$C24&"'!"&"A:Z"),COLUMN(E$2),FALSE) -> 5.0807 | G24: =VLOOKUP($A24,INDIRECT("'"&$B24&"_"&$C24&"'!"&"A:Z"),COLUMN(F$2),FALSE) -> 0.59855727 | H24: =VLOOKUP($A24,INDIRECT("'"&$B24&"_"&$C24&"'!"&"A:Z"),COLUMN(G$2),FALSE) -> 0.534764 | I24: =VLOOKUP($A24,INDIRECT("'"&$B24&"_"&$C24&"'!"&"A:Z"),COLUMN(H$2),FALSE) -> 0.506655 | J24: =VLOOKUP($A24,INDIRECT("'"&$B24&"_"&$C24&"'!"&"A:Z"),COLUMN(O$1),FALSE) -> 0.0382 | K24: =VLOOKUP($A24,INDIRECT("'"&$B24&"_"&$C24&"'!"&"A:Z"),COLUMN(P$1),FALSE) -> -0.0966 | L24: =VLOOKUP($A24,INDIRECT("'"&$B24&"_"&$C24&"'!"&"A:Z"),COLUMN(Q$1),FALSE) -> 0.0934 | M24: =VLOOKUP($A24,INDIRECT("'"&$B24&"_"&$C24&"'!"&"A:Z"),COLUMN(R$1),FALSE) -> -0.0032 | N24: =VLOOKUP($A24,INDIRECT("'"&$B24&"_"&$C24&"'!"&"A:Z"),COLUMN(Y$1),FALSE) -> 0.035 | O24: =VLOOKUP($A24,INDIRECT("'"&$B24&"_"&$C24&"'!"&"A:Z"),COLUMN($T$1),FALSE) -> 1.753 | P24: =VLOOKUP($A24,INDIRECT("'"&$B24&"_"&$C24&"'!"&"A:Z"),COLUMN($U$1),FALSE) -> 0 | Q24: =VLOOKUP($A24,INDIRECT("'"&$B24&"_"&$C24&"'!"&"A:Z"),COLUMN($M$1),FALSE) -> -77.5069 | R24: =Q24-Q$54 -> 0.0492 | S24: =SUM(R24:R26) -> 0.1016 | T24: =S24+S82 -> 0.1875 | U24: =ABS(E24-E$54)+ABS(F24-F$54) -> 0.108 | V24: =U24+U82 -> 0.2161
A25: B | B25: Mg | C25: PBESolD3 | D25: =VLOOKUP($A25,INDIRECT("'"&$B25&"_"&$C25&"'!"&"A:Z"),COLUMN(B$1),FALSE) -> Zn_Mg_C_PBESolD3_563 | E25: =VLOOKUP($A25,INDIRECT("'"&$B25&"_"&$C25&"'!"&"A:Z"),COLUMN(D$1),FALSE) -> 3.359 | F25: =VLOOKUP($A25,INDIRECT("'"&$B25&"_"&$C25&"'!"&"A:Z"),COLUMN(E$2),FALSE) -> 4.6343 | G25: =VLOOKUP($A25,INDIRECT("'"&$B25&"_"&$C25&"'!"&"A:Z"),COLUMN(F$2),FALSE) -> 0.31263451 | H25: =VLOOKUP($A25,INDIRECT("'"&$B25&"_"&$C25&"'!"&"A:Z"),COLUMN(G$2),FALSE) -> 0.27154217 | I25: =VLOOKUP($A25,INDIRECT("'"&$B25&"_"&$C25&"'!"&"A:Z"),COLUMN(H$2),FALSE) -> 0.504937 | J25: =VLOOKUP($A25,INDIRECT("'"&$B25&"_"&$C25&"'!"&"A:Z"),COLUMN(O$1),FALSE) -> 0.0836 | O25: =VLOOKUP($A25,INDIRECT("'"&$B25&"_"&$C25&"'!"&"A:Z"),COLUMN(T$1),FALSE) -> 1.774 | P25: =VLOOKUP($A25,INDIRECT("'"&$B25&"_"&$C25&"'!"&"A:Z"),COLUMN(U$1),FALSE) -> 0 | Q25: {=INDIRECT("'"&$B25&"_"&$C25&"'!"&"M30")} -> -77.4529 | R25: =Q25-Q$55 -> 0.0318
A26: C | B26: Mg | C26: PBESolD3 | D26: =VLOOKUP($A26,INDIRECT("'"&$B26&"_"&$C26&"'!"&"A:Z"),COLUMN(B$1),FALSE) -> Zn_Mg_C_PBESolD3_000 | E26: =VLOOKUP($A26,INDIRECT("'"&$B26&"_"&$C26&"'!"&"A:Z"),COLUMN(D$1),FALSE) -> 3.4541 | F26: =VLOOKUP($A26,INDIRECT("'"&$B26&"_"&$C26&"'!"&"A:Z"),COLUMN(E$2),FALSE) -> 4.2457 | G26: =VLOOKUP($A26,INDIRECT("'"&$B26&"_"&$C26&"'!"&"A:Z"),COLUMN(F$2),FALSE) -> 0 | H26: =VLOOKUP($A26,INDIRECT("'"&$B26&"_"&$C26&"'!"&"A:Z"),COLUMN(G$2),FALSE) -> 0 | I26: =VLOOKUP($A26,INDIRECT("'"&$B26&"_"&$C26&"'!"&"A:Z"),COLUMN(H$2),FALSE) -> 0.5 | J26: =VLOOKUP($A26,INDIRECT("'"&$B26&"_"&$C26&"'!"&"A:Z"),COLUMN(O$1),FALSE) -> 0 | K26: =VLOOKUP($A26,INDIRECT("'"&$B26&"_"&$C26&"'!"&"A:Z"),COLUMN(P$1),FALSE) -> 0 | L26: =VLOOKUP($A26,INDIRECT("'"&$B26&"_"&$C26&"'!"&"A:Z"),COLUMN(Q$1),FALSE) -> 0 | M26: =VLOOKUP($A26,INDIRECT("'"&$B26&"_"&$C26&"'!"&"A:Z"),COLUMN(R$1),FALSE) -> 0 | N26: =VLOOKUP($A26,INDIRECT("'"&$B26&"_"&$C26&"'!"&"A:Z"),COLUMN(Y$1),FALSE) -> 0 | O26: =VLOOKUP($A26,INDIRECT("'"&$B26&"_"&$C26&"'!"&"A:Z"),COLUMN(T$1),FALSE) -> 1.225 | P26: =VLOOKUP($A26,INDIRECT("'"&$B26&"_"&$C26&"'!"&"A:Z"),COLUMN(U$1),FALSE) -> 0 | Q26: =VLOOKUP($A26,INDIRECT("'"&$B26&"_"&$C26&"'!"&"A:Z"),COLUMN(M$1),FALSE) -> -77.5037 | R26: =Q26-Q$56 -> 0.0206
A27: V | B27: Mg | C27: PBESolD3 | D27: =VLOOKUP($A27,INDIRECT("'"&$B27&"_"&$C27&"'!"&"A:Z"),COLUMN(B$1),FALSE) -> Zn_Mg_C_PBESolD3_ver | E27: =VLOOKUP($A27,INDIRECT("'"&$B27&"_"&$C27&"'!"&"A:Z"),COLUMN(D$1),FALSE) -> 3.2513 | F27: =VLOOKUP($A27,INDIRECT("'"&$B27&"_"&$C27&"'!"&"A:Z"),COLUMN(E$2),FALSE) -> 5.0807 | G27: =VLOOKUP($A27,INDIRECT("'"&$B27&"_"&$C27&"'!"&"A:Z"),COLUMN(F$2),FALSE) -> 0 | H27: =VLOOKUP($A27,INDIRECT("'"&$B27&"_"&$C27&"'!"&"A:Z"),COLUMN(G$2),FALSE) -> 0 | I27: =VLOOKUP($A27,INDIRECT("'"&$B27&"_"&$C27&"'!"&"A:Z"),COLUMN(H$2),FALSE) -> 0.5 | J27: =VLOOKUP($A27,INDIRECT("'"&$B27&"_"&$C27&"'!"&"A:Z"),COLUMN(O$1),FALSE) -> 0.5765 | K27: =VLOOKUP($A27,INDIRECT("'"&$B27&"_"&$C27&"'!"&"A:Z"),COLUMN(P$1),FALSE) -> 58.5215 | L27: =VLOOKUP($A27,INDIRECT("'"&$B27&"_"&$C27&"'!"&"A:Z"),COLUMN(Q$1),FALSE) -> 18.9822 | M27: =VLOOKUP($A27,INDIRECT("'"&$B27&"_"&$C27&"'!"&"A:Z"),COLUMN(R$1),FALSE) -> 77.5037 | N27: =VLOOKUP($A27,INDIRECT("'"&$B27&"_"&$C27&"'!"&"A:Z"),COLUMN(Y$1),FALSE) -> 78.0802 | O27: =VLOOKUP($A27,INDIRECT("'"&$B27&"_"&$C27&"'!"&"A:Z"),COLUMN(T$1),FALSE) -> 1.548 | P27: =VLOOKUP($A27,INDIRECT("'"&$B27&"_"&$C27&"'!"&"A:Z"),COLUMN(U$1),FALSE) -> 0 | Q27: =VLOOKUP($A27,INDIRECT("'"&$B27&"_"&$C27&"'!"&"A:Z"),COLUMN(M$1),FALSE) -> 0
I28: B-A | J28: =J25-J24 -> 0.0454
A29: A | B29: Mg | C29: PBESol | D29: =VLOOKUP($A29,INDIRECT("'"&$B29&"_"&$C29&"'!"&"A:Z"),COLUMN(B$1),FALSE) -> Zn_Mg_C_PBESol_999 | E29: =VLOOKUP($A29,INDIRECT("'"&$B29&"_"&$C29&"'!"&"A:Z"),COLUMN(D$1),FALSE) -> 3.2684 | F29: =VLOOKUP($A29,INDIRECT("'"&$B29&"_"&$C29&"'!"&"A:Z"),COLUMN(E$2),FALSE) -> 5.129 | G29: =VLOOKUP($A29,INDIRECT("'"&$B29&"_"&$C29&"'!"&"A:Z"),COLUMN(F$2),FALSE) -> 0.61078696 | H29: =VLOOKUP($A29,INDIRECT("'"&$B29&"_"&$C29&"'!"&"A:Z"),COLUMN(G$2),FALSE) -> 0.54767462 | I29: =VLOOKUP($A29,INDIRECT("'"&$B29&"_"&$C29&"'!"&"A:Z"),COLUMN(H$2),FALSE) -> 0.506792 | J29: =VLOOKUP($A29,INDIRECT("'"&$B29&"_"&$C29&"'!"&"A:Z"),COLUMN(O$1),FALSE) -> -0.0106 | K29: =VLOOKUP($A29,INDIRECT("'"&$B29&"_"&$C29&"'!"&"A:Z"),COLUMN(P$1),FALSE) -> -0.1052 | L29: =VLOOKUP($A29,INDIRECT("'"&$B29&"_"&$C29&"'!"&"A:Z"),COLUMN(Q$1),FALSE) -> 0.0904 | M29: =VLOOKUP($A29,INDIRECT("'"&$B29&"_"&$C29&"'!"&"A:Z"),COLUMN(R$1),FALSE) -> -0.0148 | N29: =VLOOKUP($A29,INDIRECT("'"&$B29&"_"&$C29&"'!"&"A:Z"),COLUMN(Y$1),FALSE) -> -0.0254 | O29: =VLOOKUP($A29,INDIRECT("'"&$B29&"_"&$C29&"'!"&"A:Z"),COLUMN($T$1),FALSE) -> 1.703 | P29: =VLOOKUP($A29,INDIRECT("'"&$B29&"_"&$C29&"'!"&"A:Z"),COLUMN($U$1),FALSE) -> 0 | Q29: =VLOOKUP($A29,INDIRECT("'"&$B29&"_"&$C29&"'!"&"A:Z"),COLUMN($M$1),FALSE) -> -77.5339 | R29: =Q29-Q$54 -> 0.0222 | S29: =SUM(R29:R31) -> 0.0398 | T29: =S29+S87 -> 0.0673 | U29: =ABS(E29-E$54)+ABS(F29-F$54) -> 0.0754 | V29: =U29+U87 -> 0.1455
A30: B | B30: Mg | C30: PBESol | D30: =VLOOKUP($A30,INDIRECT("'"&$B30&"_"&$C30&"'!"&"A:Z"),COLUMN(B$1),FALSE) -> Zn_Mg_C_PBESol_500 | E30: =VLOOKUP($A30,INDIRECT("'"&$B30&"_"&$C30&"'!"&"A:Z"),COLUMN(D$1),FALSE) -> 3.3889 | F30: =VLOOKUP($A30,INDIRECT("'"&$B30&"_"&$C30&"'!"&"A:Z"),COLUMN(E$2),FALSE) -> 4.629 | G30: =VLOOKUP($A30,INDIRECT("'"&$B30&"_"&$C30&"'!"&"A:Z"),COLUMN(F$2),FALSE) -> 0.28640086 | H30: =VLOOKUP($A30,INDIRECT("'"&$B30&"_"&$C30&"'!"&"A:Z"),COLUMN(G$2),FALSE) -> 0.24841066 | I30: =VLOOKUP($A30,INDIRECT("'"&$B30&"_"&$C30&"'!"&"A:Z"),COLUMN(H$2),FALSE) -> 0.505725 | J30: =VLOOKUP($A30,INDIRECT("'"&$B30&"_"&$C30&"'!"&"A:Z"),COLUMN(O$1),FALSE) -> 0.0594 | K30: =VLOOKUP($A30,INDIRECT("'"&$B30&"_"&$C30&"'!"&"A:Z"),COLUMN(P$1),FALSE) -> 0.0217 | L30: =VLOOKUP($A30,INDIRECT("'"&$B30&"_"&$C30&"'!"&"A:Z"),COLUMN(Q$1),FALSE) -> 0.0251 | M30: =VLOOKUP($A30,INDIRECT("'"&$B30&"_"&$C30&"'!"&"A:Z"),COLUMN(R$1),FALSE) -> 0.0468 | N30: =VLOOKUP($A30,INDIRECT("'"&$B30&"_"&$C30&"'!"&"A:Z"),COLUMN(Y$1),FALSE) -> 0.1062 | O30: =VLOOKUP($A30,INDIRECT("'"&$B30&"_"&$C30&"'!"&"A:Z"),COLUMN(T$1),FALSE) -> 1.649 | P30: =VLOOKUP($A30,INDIRECT("'"&$B30&"_"&$C30&"'!"&"A:Z"),COLUMN(U$1),FALSE) -> 0 | Q30: {=INDIRECT("'"&$B30&"_"&$C30&"'!"&"M30")} -> -77.4723 | R30: =Q30-Q$55 -> 0.0124
A31: C | B31: Mg | C31: PBESol | D31: =VLOOKUP($A31,INDIRECT("'"&$B31&"_"&$C31&"'!"&"A:Z"),COLUMN(B$1),FALSE) -> Zn_Mg_C_PBESol_000 | E31: =VLOOKUP($A31,INDIRECT("'"&$B31&"_"&$C31&"'!"&"A:Z"),COLUMN(D$1),FALSE) -> 3.4767 | F31: =VLOOKUP($A31,INDIRECT("'"&$B31&"_"&$C31&"'!"&"A:Z"),COLUMN(E$2),FALSE) -> 4.2763 | G31: =VLOOKUP($A31,INDIRECT("'"&$B31&"_"&$C31&"'!"&"A:Z"),COLUMN(F$2),FALSE) -> 0 | H31: =VLOOKUP($A31,INDIRECT("'"&$B31&"_"&$C31&"'!"&"A:Z"),COLUMN(G$2),FALSE) -> 0 | I31: =VLOOKUP($A31,INDIRECT("'"&$B31&"_"&$C31&"'!"&"A:Z"),COLUMN(H$2),FALSE) -> 0.5 | J31: =VLOOKUP($A31,INDIRECT("'"&$B31&"_"&$C31&"'!"&"A:Z"),COLUMN(O$1),FALSE) -> 0 | K31: =VLOOKUP($A31,INDIRECT("'"&$B31&"_"&$C31&"'!"&"A:Z"),COLUMN(P$1),FALSE) -> 0 | L31: =VLOOKUP($A31,INDIRECT("'"&$B31&"_"&$C31&"'!"&"A:Z"),COLUMN(Q$1),FALSE) -> 0 | M31: =VLOOKUP($A31,INDIRECT("'"&$B31&"_"&$C31&"'!"&"A:Z"),COLUMN(R$1),FALSE) -> 0 | N31: =VLOOKUP($A31,INDIRECT("'"&$B31&"_"&$C31&"'!"&"A:Z"),COLUMN(Y$1),FALSE) -> 0 | O31: =VLOOKUP($A31,INDIRECT("'"&$B31&"_"&$C31&"'!"&"A:Z"),COLUMN(T$1),FALSE) -> 1.178 | P31: =VLOOKUP($A31,INDIRECT("'"&$B31&"_"&$C31&"'!"&"A:Z"),COLUMN(U$1),FALSE) -> 0 | Q31: =VLOOKUP($A31,INDIRECT("'"&$B31&"_"&$C31&"'!"&"A:Z"),COLUMN(M$1),FALSE) -> -77.5191 | R31: =Q31-Q$56 -> 0.0052
A32: V | B32: Mg | C32: PBESol | D32: =VLOOKUP($A32,INDIRECT("'"&$B32&"_"&$C32&"'!"&"A:Z"),COLUMN(B$1),FALSE) -> Zn_Mg_C_PBESol_ver | E32: =VLOOKUP($A32,INDIRECT("'"&$B32&"_"&$C32&"'!"&"A:Z"),COLUMN(D$1),FALSE) -> 3.2684 | F32: =VLOOKUP($A32,INDIRECT("'"&$B32&"_"&$C32&"'!"&"A:Z"),COLUMN(E$2),FALSE) -> 5.129 | G32: =VLOOKUP($A32,INDIRECT("'"&$B32&"_"&$C32&"'!"&"A:Z"),COLUMN(F$2),FALSE) -> 0 | H32: =VLOOKUP($A32,INDIRECT("'"&$B32&"_"&$C32&"'!"&"A:Z"),COLUMN(G$2),FALSE) -> 0 | I32: =VLOOKUP($A32,INDIRECT("'"&$B32&"_"&$C32&"'!"&"A:Z"),COLUMN(H$2),FALSE) -> 0.5 | J32: =VLOOKUP($A32,INDIRECT("'"&$B32&"_"&$C32&"'!"&"A:Z"),COLUMN(O$1),FALSE) -> 0.5179 | K32: =VLOOKUP($A32,INDIRECT("'"&$B32&"_"&$C32&"'!"&"A:Z"),COLUMN(P$1),FALSE) -> 58.5262 | L32: =VLOOKUP($A32,INDIRECT("'"&$B32&"_"&$C32&"'!"&"A:Z"),COLUMN(Q$1),FALSE) -> 18.9929 | M32: =VLOOKUP($A32,INDIRECT("'"&$B32&"_"&$C32&"'!"&"A:Z"),COLUMN(R$1),FALSE) -> 77.5191 | N32: =VLOOKUP($A32,INDIRECT("'"&$B32&"_"&$C32&"'!"&"A:Z"),COLUMN(Y$1),FALSE) -> 78.037 | O32: =VLOOKUP($A32,INDIRECT("'"&$B32&"_"&$C32&"'!"&"A:Z"),COLUMN(T$1),FALSE) -> 1.511 | P32: =VLOOKUP($A32,INDIRECT("'"&$B32&"_"&$C32&"'!"&"A:Z"),COLUMN(U$1),FALSE) -> 0 | Q32: =VLOOKUP($A32,INDIRECT("'"&$B32&"_"&$C32&"'!"&"A:Z"),COLUMN(M$1),FALSE) -> 0
I33: B-A | J33: =J30-J29 -> 0.07 | K33: =K30-K29 -> 0.1269 | L33: =L30-L29 -> -0.0653 | M33: =M30-M29 -> 0.0616 | N33: =N30-N29 -> 0.1316
A34: A | B34: Mg | C34: HFD3 | D34: =VLOOKUP($A34,INDIRECT("'"&$B34&"_"&$C34&"'!"&"A:Z"),COLUMN(B$1),FALSE) -> Zn_Mg_C_HFD3_999 | E34: =VLOOKUP($A34,INDIRECT("'"&$B34&"_"&$C34&"'!"&"A:Z"),COLUMN(D$1),FALSE) -> 3.1941 | F34: =VLOOKUP($A34,INDIRECT("'"&$B34&"_"&$C34&"'!"&"A:Z"),COLUMN(E$2),FALSE) -> 4.9122 | G34: =VLOOKUP($A34,INDIRECT("'"&$B34&"_"&$C34&"'!"&"A:Z"),COLUMN(F$2),FALSE) -> 0.55264706 | H34: =VLOOKUP($A34,INDIRECT("'"&$B34&"_"&$C34&"'!"&"A:Z"),COLUMN(G$2),FALSE) -> 0.48761936 | I34: =VLOOKUP($A34,INDIRECT("'"&$B34&"_"&$C34&"'!"&"A:Z"),COLUMN(H$2),FALSE) -> 0.50187 | J34: =VLOOKUP($A34,INDIRECT("'"&$B34&"_"&$C34&"'!"&"A:Z"),COLUMN(O$1),FALSE) -> 0.1516 | K34: =VLOOKUP($A34,INDIRECT("'"&$B34&"_"&$C34&"'!"&"A:Z"),COLUMN(P$1),FALSE) -> -0.0879 | L34: =VLOOKUP($A34,INDIRECT("'"&$B34&"_"&$C34&"'!"&"A:Z"),COLUMN(Q$1),FALSE) -> 0.0844 | M34: =VLOOKUP($A34,INDIRECT("'"&$B34&"_"&$C34&"'!"&"A:Z"),COLUMN(R$1),FALSE) -> -0.0035 | N34: =VLOOKUP($A34,INDIRECT("'"&$B34&"_"&$C34&"'!"&"A:Z"),COLUMN(Y$1),FALSE) -> 0.1481 | O34: =VLOOKUP($A34,INDIRECT("'"&$B34&"_"&$C34&"'!"&"A:Z"),COLUMN($T$1),FALSE) -> 12.767 | P34: =VLOOKUP($A34,INDIRECT("'"&$B34&"_"&$C34&"'!"&"A:Z"),COLUMN($U$1),FALSE) -> 0 | Q34: =VLOOKUP($A34,INDIRECT("'"&$B34&"_"&$C34&"'!"&"A:Z"),COLUMN($M$1),FALSE) -> -77.2931 | R34: =Q34-Q$54 -> 0.263 | S34: =SUM(R34:R36) -> 0.773 | T34: =S34+S92 -> 1.0682 | U34: =ABS(E34-E$54)+ABS(F34-F$54) -> 0.3337 | V34: =U34+U92 -> 0.7353
A35: B | B35: Mg | C35: HFD3 | D35: =VLOOKUP($A35,INDIRECT("'"&$B35&"_"&$C35&"'!"&"A:Z"),COLUMN(B$1),FALSE) -> Zn_Mg_C_HFD3_625 | E35: =VLOOKUP($A35,INDIRECT("'"&$B35&"_"&$C35&"'!"&"A:Z"),COLUMN(D$1),FALSE) -> 3.2927 | F35: =VLOOKUP($A35,INDIRECT("'"&$B35&"_"&$C35&"'!"&"A:Z"),COLUMN(E$2),FALSE) -> 4.4964 | G35: =VLOOKUP($A35,INDIRECT("'"&$B35&"_"&$C35&"'!"&"A:Z"),COLUMN(F$2),FALSE) -> 0.29073722 | H35: =VLOOKUP($A35,INDIRECT("'"&$B35&"_"&$C35&"'!"&"A:Z"),COLUMN(G$2),FALSE) -> 0.25487394 | I35: =VLOOKUP($A35,INDIRECT("'"&$B35&"_"&$C35&"'!"&"A:Z"),COLUMN(H$2),FALSE) -> 0.495513 | J35: =VLOOKUP($A35,INDIRECT("'"&$B35&"_"&$C35&"'!"&"A:Z"),COLUMN(O$1),FALSE) -> 0.1461 | O35: =VLOOKUP($A35,INDIRECT("'"&$B35&"_"&$C35&"'!"&"A:Z"),COLUMN(T$1),FALSE) -> 12.706 | P35: =VLOOKUP($A35,INDIRECT("'"&$B35&"_"&$C35&"'!"&"A:Z"),COLUMN(U$1),FALSE) -> 0 | Q35: {=INDIRECT("'"&$B35&"_"&$C35&"'!"&"M30")} -> -77.2094 | R35: =Q35-Q$55 -> 0.2753
A36: C | B36: Mg | C36: HFD3 | D36: =VLOOKUP($A36,INDIRECT("'"&$B36&"_"&$C36&"'!"&"A:Z"),COLUMN(B$1),FALSE) -> Zn_Mg_C_HFD3_000 | E36: =VLOOKUP($A36,INDIRECT("'"&$B36&"_"&$C36&"'!"&"A:Z"),COLUMN(D$1),FALSE) -> 3.3695 | F36: =VLOOKUP($A36,INDIRECT("'"&$B36&"_"&$C36&"'!"&"A:Z"),COLUMN(E$2),FALSE) -> 4.1753 | G36: =VLOOKUP($A36,INDIRECT("'"&$B36&"_"&$C36&"'!"&"A:Z"),COLUMN(F$2),FALSE) -> 0 | H36: =VLOOKUP($A36,INDIRECT("'"&$B36&"_"&$C36&"'!"&"A:Z"),COLUMN(G$2),FALSE) -> 0 | I36: =VLOOKUP($A36,INDIRECT("'"&$B36&"_"&$C36&"'!"&"A:Z"),COLUMN(H$2),FALSE) -> 0.5 | J36: =VLOOKUP($A36,INDIRECT("'"&$B36&"_"&$C36&"'!"&"A:Z"),COLUMN(O$1),FALSE) -> 0 | K36: =VLOOKUP($A36,INDIRECT("'"&$B36&"_"&$C36&"'!"&"A:Z"),COLUMN(P$1),FALSE) -> 0 | L36: =VLOOKUP($A36,INDIRECT("'"&$B36&"_"&$C36&"'!"&"A:Z"),COLUMN(Q$1),FALSE) -> 0 | M36: =VLOOKUP($A36,INDIRECT("'"&$B36&"_"&$C36&"'!"&"A:Z"),COLUMN(R$1),FALSE) -> 0 | N36: =VLOOKUP($A36,INDIRECT("'"&$B36&"_"&$C36&"'!"&"A:Z"),COLUMN(Y$1),FALSE) -> 0 | O36: =VLOOKUP($A36,INDIRECT("'"&$B36&"_"&$C36&"'!"&"A:Z"),COLUMN(T$1),FALSE) -> 12.177 | P36: =VLOOKUP($A36,INDIRECT("'"&$B36&"_"&$C36&"'!"&"A:Z"),COLUMN(U$1),FALSE) -> 0 | Q36: =VLOOKUP($A36,INDIRECT("'"&$B36&"_"&$C36&"'!"&"A:Z"),COLUMN(M$1),FALSE) -> -77.2896 | R36: =Q36-Q$56 -> 0.2347
A37: V | B37: Mg | C37: HFD3 | D37: =VLOOKUP($A37,INDIRECT("'"&$B37&"_"&$C37&"'!"&"A:Z"),COLUMN(B$1),FALSE) -> Zn_Mg_C_HFD3_ver | E37: =VLOOKUP($A37,INDIRECT("'"&$B37&"_"&$C37&"'!"&"A:Z"),COLUMN(D$1),FALSE) -> 3.1941 | F37: =VLOOKUP($A37,INDIRECT("'"&$B37&"_"&$C37&"'!"&"A:Z"),COLUMN(E$2),FALSE) -> 4.9122 | G37: =VLOOKUP($A37,INDIRECT("'"&$B37&"_"&$C37&"'!"&"A:Z"),COLUMN(F$2),FALSE) -> 0 | H37: =VLOOKUP($A37,INDIRECT("'"&$B37&"_"&$C37&"'!"&"A:Z"),COLUMN(G$2),FALSE) -> 0 | I37: =VLOOKUP($A37,INDIRECT("'"&$B37&"_"&$C37&"'!"&"A:Z"),COLUMN(H$2),FALSE) -> 0.5 | J37: =VLOOKUP($A37,INDIRECT("'"&$B37&"_"&$C37&"'!"&"A:Z"),COLUMN(O$1),FALSE) -> 0.7539 | K37: =VLOOKUP($A37,INDIRECT("'"&$B37&"_"&$C37&"'!"&"A:Z"),COLUMN(P$1),FALSE) -> 58.3548 | L37: =VLOOKUP($A37,INDIRECT("'"&$B37&"_"&$C37&"'!"&"A:Z"),COLUMN(Q$1),FALSE) -> 18.9348 | M37: =VLOOKUP($A37,INDIRECT("'"&$B37&"_"&$C37&"'!"&"A:Z"),COLUMN(R$1),FALSE) -> 77.2896 | N37: =VLOOKUP($A37,INDIRECT("'"&$B37&"_"&$C37&"'!"&"A:Z"),COLUMN(Y$1),FALSE) -> 78.0435 | O37: =VLOOKUP($A37,INDIRECT("'"&$B37&"_"&$C37&"'!"&"A:Z"),COLUMN(T$1),FALSE) -> 12.658 | P37: =VLOOKUP($A37,INDIRECT("'"&$B37&"_"&$C37&"'!"&"A:Z"),COLUMN(U$1),FALSE) -> 0 | Q37: =VLOOKUP($A37,INDIRECT("'"&$B37&"_"&$C37&"'!"&"A:Z"),COLUMN(M$1),FALSE) -> 0 | R37: =Q37-Q$56 -> 77.5243
I38: B-A | J38: =J35-J34 -> -0.0055
A39: A | B39: Mg | C39: HF | D39: =VLOOKUP($A39,INDIRECT("'"&$B39&"_"&$C39&"'!"&"A:Z"),COLUMN(B$1),FALSE) -> Zn_Mg_C_HF_999 | E39: =VLOOKUP($A39,INDIRECT("'"&$B39&"_"&$C39&"'!"&"A:Z"),COLUMN(D$1),FALSE) -> 3.269 | F39: =VLOOKUP($A39,INDIRECT("'"&$B39&"_"&$C39&"'!"&"A:Z"),COLUMN(E$2),FALSE) -> 5.1724 | G39: =VLOOKUP($A39,INDIRECT("'"&$B39&"_"&$C39&"'!"&"A:Z"),COLUMN(F$2),FALSE) -> 0.62662592 | H39: =VLOOKUP($A39,INDIRECT("'"&$B39&"_"&$C39&"'!"&"A:Z"),COLUMN(G$2),FALSE) -> 0.56828124 | I39: =VLOOKUP($A39,INDIRECT("'"&$B39&"_"&$C39&"'!"&"A:Z"),COLUMN(H$2),FALSE) -> 0.501629 | J39: =VLOOKUP($A39,INDIRECT("'"&$B39&"_"&$C39&"'!"&"A:Z"),COLUMN(O$1),FALSE) -> -0.1527 | K39: =VLOOKUP($A39,INDIRECT("'"&$B39&"_"&$C39&"'!"&"A:Z"),COLUMN(P$1),FALSE) -> -0.115 | L39: =VLOOKUP($A39,INDIRECT("'"&$B39&"_"&$C39&"'!"&"A:Z"),COLUMN(Q$1),FALSE) -> 0.0998 | M39: =VLOOKUP($A39,INDIRECT("'"&$B39&"_"&$C39&"'!"&"A:Z"),COLUMN(R$1),FALSE) -> -0.0152 | N39: =VLOOKUP($A39,INDIRECT("'"&$B39&"_"&$C39&"'!"&"A:Z"),COLUMN(Y$1),FALSE) -> -0.1679 | O39: =VLOOKUP($A39,INDIRECT("'"&$B39&"_"&$C39&"'!"&"A:Z"),COLUMN($T$1),FALSE) -> 12.181 | P39: =VLOOKUP($A39,INDIRECT("'"&$B39&"_"&$C39&"'!"&"A:Z"),COLUMN($U$1),FALSE) -> 0 | Q39: =VLOOKUP($A39,INDIRECT("'"&$B39&"_"&$C39&"'!"&"A:Z"),COLUMN($M$1),FALSE) -> -77.5395 | R39: =Q39-Q$54 -> 0.0166 | S39: =SUM(R39:R41) -> 0.0194 | T39: =S39+S97 -> 0.0273 | U39: =ABS(E39-E$54)+ABS(F39-F$54) -> 0.0326 | V39: =U39+U97 -> 0.2086
A40: B | B40: Mg | C40: HF | D40: =VLOOKUP($A40,INDIRECT("'"&$B40&"_"&$C40&"'!"&"A:Z"),COLUMN(B$1),FALSE) -> Zn_Mg_C_HF_313 | E40: =VLOOKUP($A40,INDIRECT("'"&$B40&"_"&$C40&"'!"&"A:Z"),COLUMN(D$1),FALSE) -> 3.4368 | F40: =VLOOKUP($A40,INDIRECT("'"&$B40&"_"&$C40&"'!"&"A:Z"),COLUMN(E$2),FALSE) -> 4.4545 | G40: =VLOOKUP($A40,INDIRECT("'"&$B40&"_"&$C40&"'!"&"A:Z"),COLUMN(F$2),FALSE) -> 0.15137282 | H40: =VLOOKUP($A40,INDIRECT("'"&$B40&"_"&$C40&"'!"&"A:Z"),COLUMN(G$2),FALSE) -> 0.13838795 | I40: =VLOOKUP($A40,INDIRECT("'"&$B40&"_"&$C40&"'!"&"A:Z"),COLUMN(H$2),FALSE) -> 0.496632 | J40: =VLOOKUP($A40,INDIRECT("'"&$B40&"_"&$C40&"'!"&"A:Z"),COLUMN(O$1),FALSE) -> 0.0212 | O40: =VLOOKUP($A40,INDIRECT("'"&$B40&"_"&$C40&"'!"&"A:Z"),COLUMN(T$1),FALSE) -> 11.835 | P40: =VLOOKUP($A40,INDIRECT("'"&$B40&"_"&$C40&"'!"&"A:Z"),COLUMN(U$1),FALSE) -> 0 | Q40: {=INDIRECT("'"&$B40&"_"&$C40&"'!"&"M30")} -> -77.4819 | R40: =Q40-Q$55 -> 0.0028
A41: C | B41: Mg | C41: HF | D41: =VLOOKUP($A41,INDIRECT("'"&$B41&"_"&$C41&"'!"&"A:Z"),COLUMN(B$1),FALSE) -> Zn_Mg_C_HF_000 | E41: =VLOOKUP($A41,INDIRECT("'"&$B41&"_"&$C41&"'!"&"A:Z"),COLUMN(D$1),FALSE) -> 3.4735 | F41: =VLOOKUP($A41,INDIRECT("'"&$B41&"_"&$C41&"'!"&"A:Z"),COLUMN(E$2),FALSE) -> 4.3132 | G41: =VLOOKUP($A41,INDIRECT("'"&$B41&"_"&$C41&"'!"&"A:Z"),COLUMN(F$2),FALSE) -> 0 | H41: =VLOOKUP($A41,INDIRECT("'"&$B41&"_"&$C41&"'!"&"A:Z"),COLUMN(G$2),FALSE) -> 0 | I41: =VLOOKUP($A41,INDIRECT("'"&$B41&"_"&$C41&"'!"&"A:Z"),COLUMN(H$2),FALSE) -> 0.5 | J41: =VLOOKUP($A41,INDIRECT("'"&$B41&"_"&$C41&"'!"&"A:Z"),COLUMN(O$1),FALSE) -> 0 | K41: =VLOOKUP($A41,INDIRECT("'"&$B41&"_"&$C41&"'!"&"A:Z"),COLUMN(P$1),FALSE) -> 0 | L41: =VLOOKUP($A41,INDIRECT("'"&$B41&"_"&$C41&"'!"&"A:Z"),COLUMN(Q$1),FALSE) -> 0 | M41: =VLOOKUP($A41,INDIRECT("'"&$B41&"_"&$C41&"'!"&"A:Z"),COLUMN(R$1),FALSE) -> 0 | N41: =VLOOKUP($A41,INDIRECT("'"&$B41&"_"&$C41&"'!"&"A:Z"),COLUMN(Y$1),FALSE) -> 0 | O41: =VLOOKUP($A41,INDIRECT("'"&$B41&"_"&$C41&"'!"&"A:Z"),COLUMN(T$1),FALSE) -> 11.663 | P41: =VLOOKUP($A41,INDIRECT("'"&$B41&"_"&$C41&"'!"&"A:Z"),COLUMN(U$1),FALSE) -> 0 | Q41: =VLOOKUP($A41,INDIRECT("'"&$B41&"_"&$C41&"'!"&"A:Z"),COLUMN(M$1),FALSE) -> -77.5243 | R41: =Q41-Q$56 -> 0
...

Sheet Mg_HFD3
A1: HFD3 | C1: calc # = | D1: =COUNT(D41:D502)-6 -> 23 | J1: VASP energies | O1: change to h-ZnMgO2 | T1: Bandgap | W1: DFT KPOINTS 664 corr to MP2 332 400 | Z1: HF KPOINTS 996 corr to MP2 332 400 | AD1: MP2 332 520 | AH1: MP2 443 520
A2: Struct | B2: file | C2: RC | D2: a | E2: c | F2: z(Zn-O) | G2: z(Mg-O) | H2: interplane ratio | J2: =A1 -> HFD3 | K2: HF | L2: correl | M2: MP2 332 400 | O2: =A1 -> HFD3 | P2: HF | Q2: correl | R2: MP2 332 400 | T2: =A1 -> HFD3 | U2: HF | W2: DFT@332 | X2: corr | Y2: MP2 w DFT KP corr | Z2: HF at 996 | AA2: corr | AB2: MP2 w KP corr | AD2: total | AE2: diff to C | AF2: MP2 332 520 corr | AH2: total | AI2: diff to C
A3: A' | B3: =B39 -> Zn_Mg_C_HFD3_999 | C3: =-C39 -> -1 | D3: =D39 -> 3.1941 | E3: =E39 -> 4.9122 | F3: =-F39 -> -0.55264706 | G3: =-G39 -> -0.48761936 | H3: =H39 -> 0.50187 | J3: =J39 -> -61.9999 | K3: =K39 -> -58.4427 | L3: =L39 -> -18.8504 | M3: =M39 -> -77.2931 | O3: =O39 -> 0.1516 | P3: =P39 -> -0.0879 | Q3: =Q39 -> 0.0844 | R3: =R39 -> -0.0035 | T3: =T39 -> 12.767 | U3: =U39 -> 0 | W3: =W39 -> 0 | X3: =X39 -> 0.1516 | Y3: =R3+X3 -> 0.1481 | Z3: =Z39 -> 0 | AA3: =AA39 -> 0.0879 | AB3: =AA3+R3 -> 0.0844 | AD3: =AD39 -> 0 | AE3: =AE39 -> 0 | AF3: =AF39 -> 0.0879 | AH3: =AH39 -> 0 | AI3: =AI39 -> 0
B4: =B38 -> Zn_Mg_C_HFD3_969 | C4: =-C38 -> -0.96874407 | D4: =D38 -> 3.2017 | E4: =E38 -> 4.8829 | F4: =-F38 -> -0.53318827 | G4: =-G38 -> -0.46957873 | H4: =H38 -> 0.502018 | J4: =J38 -> -61.9995 | K4: =K38 -> 0 | L4: =L38 -> 0 | M4: =M38 -> 0 | O4: =O38 -> 0.152 | P4: =P38 -> 58.3548 | Q4: =Q38 -> 18.9348 | R4: =R38 -> 77.2896 | T4: =T38 -> 12.777 | U4: =U38 -> 0 | W4: =W38 -> 0 | X4: =X38 -> 0.152 | Y4: =R4+X4 -> 77.4416 | Z4: =Z38 -> 0 | AA4: =AA38 -> -58.3548 | AB4: =AA4+R4 -> 18.9348 | AD4: =AD38 -> 0 | AE4: =AE38 -> 0 | AF4: =AF38 -> -58.3548
B5: =B37 -> Zn_Mg_C_HFD3_938 | C5: =-C37 -> -0.93749718 | D5: =D37 -> 3.2094 | E5: =E37 -> 4.853 | F5: =-F37 -> -0.51334549 | G5: =-G37 -> -0.45158621 | H5: =H37 -> 0.502059 | J5: =J37 -> -61.9985 | K5: =K37 -> 0 | L5: =L37 -> 0 | M5: =M37 -> 0 | O5: =O37 -> 0.153 | P5: =P37 -> 58.3548 | Q5: =Q37 -> 18.9348 | R5: =R37 -> 77.2896 | T5: =T37 -> 12.787 | U5: =U37 -> 0 | W5: =W37 -> 0 | X5: =X37 -> 0.153 | Y5: =R5+X5 -> 77.4426 | Z5: =Z37 -> 0 | AA5: =AA37 -> -58.3548 | AB5: =AA5+R5 -> 18.9348 | AD5: =AD37 -> 0 | AE5: =AE37 -> 0 | AF5: =AF37 -> -58.3548
B6: =B36 -> Zn_Mg_C_HFD3_875 | C6: =-C36 -> -0.87499435 | D6: =D36 -> 3.2251 | E6: =E36 -> 4.7901 | F6: =-F36 -> -0.47265354 | G6: =-G36 -> -0.41462148 | H6: =H36 -> 0.501868 | J6: =J36 -> -61.9956 | K6: =K36 -> 0 | L6: =L36 -> 0 | M6: =M36 -> 0 | O6: =O36 -> 0.1559 | P6: =P36 -> 58.3548 | Q6: =Q36 -> 18.9348 | R6: =R36 -> 77.2896 | T6: =T36 -> 12.812 | U6: =U36 -> 0 | W6: =W36 -> 0 | X6: =X36 -> 0.1559 | Y6: =R6+X6 -> 77.4455 | Z6: =Z36 -> 0 | AA6: =AA36 -> -58.3548 | AB6: =AA6+R6 -> 18.9348 | AD6: =AD36 -> 0 | AE6: =AE36 -> 0 | AF6: =AF36 -> -58.3548
B7: =B35 -> Zn_Mg_C_HFD3_813 | C7: =-C35 -> -0.81250056 | D7: =D35 -> 3.2413 | E7: =E35 -> 4.7225 | F7: =-F35 -> -0.42999779 | G7: =-G35 -> -0.37634075 | H7: =H35 -> 0.501162 | J7: =J35 -> -61.9932 | K7: =K35 -> 0 | L7: =L35 -> 0 | M7: =M35 -> 0 | O7: =O35 -> 0.1583 | P7: =P35 -> 58.3548 | Q7: =Q35 -> 18.9348 | R7: =R35 -> 77.2896 | T7: =T35 -> 12.845 | U7: =U35 -> 0 | W7: =W35 -> 0 | X7: =X35 -> 0.1583 | Y7: =R7+X7 -> 77.4479 | Z7: =Z35 -> 0 | AA7: =AA35 -> -58.3548 | AB7: =AA7+R7 -> 18.9348 | AD7: =AD35 -> 0 | AE7: =AE35 -> 0 | AF7: =AF35 -> -58.3548
B8: =B34 -> Zn_Mg_C_HFD3_750 | C8: =-C34 -> -0.74999774 | D8: =D34 -> 3.2581 | E8: =E34 -> 4.6496 | F8: =-F34 -> -0.38503803 | G8: =-G34 -> -0.33636136 | H8: =H34 -> 0.499835 | J8: =J34 -> -61.9929 | K8: =K34 -> 0 | L8: =L34 -> 0 | M8: =M34 -> 0 | O8: =O34 -> 0.1586 | P8: =P34 -> 58.3548 | Q8: =Q34 -> 18.9348 | R8: =R34 -> 77.2896 | T8: =T34 -> 12.885 | U8: =U34 -> 0 | W8: =W34 -> 0 | X8: =X34 -> 0.1586 | Y8: =R8+X8 -> 77.4482 | Z8: =Z34 -> 0 | AA8: =AA34 -> -58.3548 | AB8: =AA8+R8 -> 18.9348 | AD8: =AD34 -> 0 | AE8: =AE34 -> 0 | AF8: =AF34 -> -58.3548
B9: =B33 -> Zn_Mg_C_HFD3_688 | C9: =-C33 -> -0.68749492 | D9: =D33 -> 3.2755 | E9: =E33 -> 4.573 | F9: =-F33 -> -0.33809561 | G9: =-G33 -> -0.29544324 | H9: =H33 -> 0.497872 | J9: =J33 -> -61.9966 | K9: =K33 -> 0 | L9: =L33 -> 0 | M9: =M33 -> 0 | O9: =O33 -> 0.1549 | P9: =P33 -> 58.3548 | Q9: =Q33 -> 18.9348 | R9: =R33 -> 77.2896 | T9: =T33 -> 12.857 | U9: =U33 -> 0 | W9: =W33 -> 0 | X9: =X33 -> 0.1549 | Y9: =R9+X9 -> 77.4445 | Z9: =Z33 -> 0 | AA9: =AA33 -> -58.3548 | AB9: =AA9+R9 -> 18.9348 | AD9: =AD33 -> 0 | AE9: =AE33 -> 0 | AF9: =AF33 -> -58.3548
A10: B' | B10: =B32 -> Zn_Mg_C_HFD3_625 | C10: =-C32 -> -0.62500113 | D10: =D32 -> 3.2927 | E10: =E32 -> 4.4964 | F10: =-F32 -> -0.29073722 | G10: =-G32 -> -0.25487394 | H10: =H32 -> 0.495513 | J10: =J32 -> -62.0054 | K10: =K32 -> 0 | L10: =L32 -> 0 | M10: =M32 -> 0 | O10: =O32 -> 0.1461 | P10: =P32 -> 58.3548 | Q10: =Q32 -> 18.9348 | R10: =R32 -> 77.2896 | T10: =T32 -> 12.706 | U10: =U32 -> 0 | W10: =W32 -> 0 | X10: =X32 -> 0.1461 | Y10: =R10+X10 -> 77.4357 | Z10: =Z32 -> 0 | AA10: =AA32 -> -58.3548 | AB10: =AA10+R10 -> 18.9348 | AD10: =AD32 -> 0 | AE10: =AE32 -> 0 | AF10: =AF32 -> -58.3548
B11: =B31 -> Zn_Mg_C_HFD3_563 | C11: =-C31 -> -0.56249831 | D11: =D31 -> 3.3091 | E11: =E31 -> 4.4253 | F11: =-F31 -> -0.24521472 | G11: =-G31 -> -0.21663171 | H11: =H31 -> 0.49318 | J11: =J31 -> -62.0195 | K11: =K31 -> 0 | L11: =L31 -> 0 | M11: =M31 -> 0 | O11: =O31 -> 0.132 | P11: =P31 -> 58.3548 | Q11: =Q31 -> 18.9348 | R11: =R31 -> 77.2896 | T11: =T31 -> 12.57 | U11: =U31 -> 0 | W11: =W31 -> 0 | X11: =X31 -> 0.132 | Y11: =R11+X11 -> 77.4216 | Z11: =Z31 -> 0 | AA11: =AA31 -> -58.3548 | AB11: =AA11+R11 -> 18.9348 | AD11: =AD31 -> 0 | AE11: =AE31 -> 0 | AF11: =AF31 -> -58.3548
B12: =B30 -> Zn_Mg_C_HFD3_500 | C12: =-C30 -> -0.49999548 | D12: =D30 -> 3.3234 | E12: =E30 -> 4.364 | F12: =-F30 -> -0.20416974 | G12: =-G30 -> -0.18210536 | H12: =H30 -> 0.491468 | J12: =J30 -> -62.0379 | K12: =K30 -> -58.3033 | L12: =L30 -> -18.9061 | M12: =M30 -> -77.2094 | O12: =O30 -> 0.1136 | P12: =P30 -> 0.0515 | Q12: =Q30 -> 0.0287 | R12: =R30 -> 0.0802 | T12: =T30 -> 12.459 | U12: =U30 -> 0 | W12: =W30 -> 0 | X12: =X30 -> 0.1136 | Y12: =R12+X12 -> 0.1938 | Z12: =Z30 -> 0 | AA12: =AA30 -> -0.0515 | AB12: =AA12+R12 -> 0.0287 | AD12: =AD30 -> 0 | AE12: =AE30 -> 0 | AF12: =AF30 -> -0.0515
B13: =B29 -> Zn_Mg_C_HFD3_438 | C13: =-C29 -> -0.43750169 | D13: =D29 -> 3.3353 | E13: =E29 -> 4.3143 | F13: =-F29 -> -0.16867619 | G13: =-G29 -> -0.15202299 | H13: =H29 -> 0.490694 | J13: =J29 -> -62.0586 | K13: =K29 -> 0 | L13: =L29 -> 0 | M13: =M29 -> 0 | O13: =O29 -> 0.0929 | P13: =P29 -> 58.3548 | Q13: =Q29 -> 18.9348 | R13: =R29 -> 77.2896 | T13: =T29 -> 12.375 | U13: =U29 -> 0 | W13: =W29 -> 0 | X13: =X29 -> 0.0929 | Y13: =R13+X13 -> 77.3825 | Z13: =Z29 -> 0 | AA13: =AA29 -> -58.3548 | AB13: =AA13+R13 -> 18.9348 | AD13: =AD29 -> 0 | AE13: =AE29 -> 0 | AF13: =AF29 -> -58.3548
B14: =B28 -> Zn_Mg_C_HFD3_375 | C14: =-C28 -> -0.37499887 | D14: =D28 -> 3.345 | E14: =E28 -> 4.274 | F14: =-F28 -> -0.13775957 | G14: =-G28 -> -0.12531368 | H14: =H28 -> 0.490744 | J14: =J28 -> -62.0797 | K14: =K28 -> 0 | L14: =L28 -> 0 | M14: =M28 -> 0 | O14: =O28 -> 0.0718 | P14: =P28 -> 58.3548 | Q14: =Q28 -> 18.9348 | R14: =R28 -> 77.2896 | T14: =T28 -> 12.312 | U14: =U28 -> 0 | W14: =W28 -> 0 | X14: =X28 -> 0.0718 | Y14: =R14+X14 -> 77.3614 | Z14: =Z28 -> 0 | AA14: =AA28 -> -58.3548 | AB14: =AA14+R14 -> 18.9348 | AD14: =AD28 -> 0 | AE14: =AE28 -> 0 | AF14: =AF28 -> -58.3548
B15: =B27 -> Zn_Mg_C_HFD3_313 | C15: =-C27 -> -0.31249605 | D15: =D27 -> 3.3529 | E15: =E27 -> 4.2421 | F15: =-F27 -> -0.11019279 | G15: =-G27 -> -0.10125044 | H15: =H27 -> 0.491403 | J15: =J27 -> -62.0997 | K15: =K27 -> 0 | L15: =L27 -> 0 | M15: =M27 -> 0 | O15: =O27 -> 0.0518 | P15: =P27 -> 58.3548 | Q15: =Q27 -> 18.9348 | R15: =R27 -> 77.2896 | T15: =T27 -> 12.265 | U15: =U27 -> 0 | W15: =W27 -> 0 | X15: =X27 -> 0.0518 | Y15: =R15+X15 -> 77.3414 | Z15: =Z27 -> 0 | AA15: =AA27 -> -58.3548 | AB15: =AA15+R15 -> 18.9348 | AD15: =AD27 -> 0 | AE15: =AE27 -> 0 | AF15: =AF27 -> -58.3548
B16: =B26 -> Zn_Mg_C_HFD3_250 | C16: =-C26 -> -0.25000226 | D16: =D26 -> 3.359 | E16: =E26 -> 4.2173 | F16: =-F26 -> -0.085682884 | G16: =-G26 -> -0.079091244 | H16: =H26 -> 0.492658 | J16: =J26 -> -62.1174 | K16: =K26 -> 0 | L16: =L26 -> 0 | M16: =M26 -> 0 | O16: =O26 -> 0.0341 | P16: =P26 -> 58.3548 | Q16: =Q26 -> 18.9348 | R16: =R26 -> 77.2896 | T16: =T26 -> 12.229 | U16: =U26 -> 0 | W16: =W26 -> 0 | X16: =X26 -> 0.0341 | Y16: =R16+X16 -> 77.3237 | Z16: =Z26 -> 0 | AA16: =AA26 -> -58.3548 | AB16: =AA16+R16 -> 18.9348 | AD16: =AD26 -> 0 | AE16: =AE26 -> 0 | AF16: =AF26 -> -58.3548
B17: =B25 -> Zn_Mg_C_HFD3_188 | C17: =-C25 -> -0.18749944 | D17: =D25 -> 3.3636 | E17: =E25 -> 4.1986 | F17: =-F25 -> -0.062865638 | G17: =-G25 -> -0.05820939 | H17: =H25 -> 0.494229 | J17: =J25 -> -62.1319 | K17: =K25 -> 0 | L17: =L25 -> 0 | M17: =M25 -> 0 | O17: =O25 -> 0.0196 | P17: =P25 -> 58.3548 | Q17: =Q25 -> 18.9348 | R17: =R25 -> 77.2896 | T17: =T25 -> 12.204 | U17: =U25 -> 0 | W17: =W25 -> 0 | X17: =X25 -> 0.0196 | Y17: =R17+X17 -> 77.3092 | Z17: =Z25 -> 0 | AA17: =AA25 -> -58.3548 | AB17: =AA17+R17 -> 18.9348 | AD17: =AD25 -> 0 | AE17: =AE25 -> 0 | AF17: =AF25 -> -58.3548
B18: =B24 -> Zn_Mg_C_HFD3_125 | C18: =-C24 -> -0.12499661 | D18: =D24 -> 3.3669 | E18: =E24 -> 4.1855 | F18: =-F24 -> -0.041218804 | G18: =-G24 -> -0.038427075 | H18: =H24 -> 0.496019 | J18: =J24 -> -62.1427 | K18: =K24 -> 0 | L18: =L24 -> 0 | M18: =M24 -> 0 | O18: =O24 -> 0.0088 | P18: =P24 -> 58.3548 | Q18: =Q24 -> 18.9348 | R18: =R24 -> 77.2896 | T18: =T24 -> 12.187 | U18: =U24 -> 0 | W18: =W24 -> 0 | X18: =X24 -> 0.0088 | Y18: =R18+X18 -> 77.2984 | Z18: =Z24 -> 0 | AA18: =AA24 -> -58.3548 | AB18: =AA18+R18 -> 18.9348 | AD18: =AD24 -> 0 | AE18: =AE24 -> 0 | AF18: =AF24 -> -58.3548
B19: =B23 -> Zn_Mg_C_HFD3_063 | C19: =-C23 -> -0.062502825 | D19: =D23 -> 3.3687 | E19: =E23 -> 4.1781 | F19: =-F23 -> -0.020531183 | G19: =-G23 -> -0.01913152 | H19: =H23 -> 0.497999 | J19: =J23 -> -62.1493 | K19: =K23 -> 0 | L19: =L23 -> 0 | M19: =M23 -> 0 | O19: =O23 -> 0.0022 | P19: =P23 -> 58.3548 | Q19: =Q23 -> 18.9348 | R19: =R23 -> 77.2896 | T19: =T23 -> 12.177 | U19: =U23 -> 0 | W19: =W23 -> 0 | X19: =X23 -> 0.0022 | Y19: =R19+X19 -> 77.2918 | Z19: =Z23 -> 0 | AA19: =AA23 -> -58.3548 | AB19: =AA19+R19 -> 18.9348 | AD19: =AD23 -> 0 | AE19: =AE23 -> 0 | AF19: =AF23 -> -58.3548
B20: =B22 -> Zn_Mg_C_HFD3_031 | C20: =-C22 -> -0.031246893 | D20: =D22 -> 3.3692 | E20: =E22 -> 4.176 | F20: =-F22 -> -0.010227024 | G20: =-G22 -> -0.009529632 | H20: =H22 -> 0.498992 | J20: =J22 -> -62.1509 | K20: =K22 -> 0 | L20: =L22 -> 0 | M20: =M22 -> 0 | O20: =O22 -> 0.0006 | P20: =P22 -> 58.3548 | Q20: =Q22 -> 18.9348 | R20: =R22 -> 77.2896 | T20: =T22 -> 12.175 | U20: =U22 -> 0 | W20: =W22 -> 0 | X20: =X22 -> 0.0006 | Y20: =R20+X20 -> 77.2902 | Z20: =Z22 -> 0 | AA20: =AA22 -> -58.3548 | AB20: =AA20+R20 -> 18.9348 | AD20: =AD22 -> 0 | AE20: =AE22 -> 0 | AF20: =AF22 -> -58.3548
A21: C | B21: =Mg_HFD3!B45 -> Zn_Mg_C_HFD3_000 | C21: =(0.5-AV45)/(0.5-AV$63) -> 0 | D21: =J45 -> 3.3695 | E21: =L45 -> 4.1753 | F21: =E21*ABS(AS45-AV45) -> 0 | G21: =E21*(ABS(MOD(AT45-AU45+2.5,1)-0.5)) -> 0 | H21: =MOD(AS45-AT45,1) -> 0.5 | J21: =R45 -> -62.1515 | K21: =R69 -> -58.3548 | L21: =AW69 -> -18.9348 | M21: =K21+L21 -> -77.2896 | O21: =J21-J$21 -> 0 | P21: =K21-K$21 -> 0 | Q21: =L21-L$21 -> 0 | R21: =M21-M$21 -> 0 | T21: =Z47 -> 12.177 | U21: =V115 -> 0 | W21: =R92-R$92 -> 0 | X21: =O21-W21 -> 0 | Y21: =R21+X21 -> 0 | Z21: =R161-R$161 -> 0 | AA21: =Z21-P21 -> 0 | AB21: =AA21+R21 -> 0 | AD21: =R115+AW115 -> 0 | AE21: =AD21-AD$21 -> 0 | AF21: =AE21+AA21 -> 0 | AH21: =R138+AW138 -> 0 | AI21: =AH21-AH$21 -> 0
B22: =Mg_HFD3!B46 -> Zn_Mg_C_HFD3_031 | C22: =(0.5-AV46)/(0.5-AV$63) -> 0.031246893 | D22: =Mg_HFD3!J46 -> 3.3692 | E22: =L46 -> 4.176 | F22: =E22*ABS(AS46-AV46) -> 0.010227024 | G22: =E22*(ABS(MOD(AT46-AU46+2.5,1)-0.5)) -> 0.009529632 | H22: =MOD(AS46-AT46,1) -> 0.498992 | J22: =R46 -> -62.1509 | K22: =R70 -> 0 | L22: =AW70 -> 0 | M22: =K22+L22 -> 0 | O22: =J22-J$21 -> 0.0006 | P22: =K22-K$21 -> 58.3548 | Q22: =L22-L$21 -> 18.9348 | R22: =M22-M$21 -> 77.2896 | T22: =Z46 -> 12.175 | U22: =V116 -> 0 | W22: =R93-R$92 -> 0 | X22: =O22-W22 -> 0.0006 | Y22: =R22+X22 -> 77.2902 | Z22: =R162-R$161 -> 0 | AA22: =Z22-P22 -> -58.3548 | AB22: =AA22+R22 -> 18.9348 | AD22: =R116+AW116 -> 0 | AE22: =AD22-AD$21 -> 0 | AF22: =AE22+AA22 -> -58.3548
B23: =Mg_HFD3!B47 -> Zn_Mg_C_HFD3_063 | C23: =(0.5-AV47)/(0.5-AV$63) -> 0.062502825 | D23: =Mg_HFD3!J47 -> 3.3687 | E23: =L47 -> 4.1781 | F23: =E23*ABS(AS47-AV47) -> 0.020531183 | G23: =E23*(ABS(MOD(AT47-AU47+2.5,1)-0.5)) -> 0.01913152 | H23: =MOD(AS47-AT47,1) -> 0.497999 | J23: =R47 -> -62.1493 | K23: =R71 -> 0 | L23: =AW71 -> 0 | M23: =K23+L23 -> 0 | O23: =J23-J$21 -> 0.0022 | P23: =K23-K$21 -> 58.3548 | Q23: =L23-L$21 -> 18.9348 | R23: =M23-M$21 -> 77.2896 | T23: =Z47 -> 12.177 | U23: =V117 -> 0 | W23: =R94-R$92 -> 0 | X23: =O23-W23 -> 0.0022 | Y23: =R23+X23 -> 77.2918 | Z23: =R163-R$161 -> 0 | AA23: =Z23-P23 -> -58.3548 | AB23: =AA23+R23 -> 18.9348 | AD23: =R117+AW117 -> 0 | AE23: =AD23-AD$21 -> 0 | AF23: =AE23+AA23 -> -58.3548
B24: =Mg_HFD3!B48 -> Zn_Mg_C_HFD3_125 | C24: =(0.5-AV48)/(0.5-AV$63) -> 0.12499661 | D24: =Mg_HFD3!J48 -> 3.3669 | E24: =L48 -> 4.1855 | F24: =E24*ABS(AS48-AV48) -> 0.041218804 | G24: =E24*(ABS(MOD(AT48-AU48+2.5,1)-0.5)) -> 0.038427075 | H24: =MOD(AS48-AT48,1) -> 0.496019 | J24: =R48 -> -62.1427 | K24: =R72 -> 0 | L24: =AW72 -> 0 | M24: =K24+L24 -> 0 | O24: =J24-J$21 -> 0.0088 | P24: =K24-K$21 -> 58.3548 | Q24: =L24-L$21 -> 18.9348 | R24: =M24-M$21 -> 77.2896 | T24: =Z48 -> 12.187 | U24: =V118 -> 0 | W24: =R95-R$92 -> 0 | X24: =O24-W24 -> 0.0088 | Y24: =R24+X24 -> 77.2984 | Z24: =R164-R$161 -> 0 | AA24: =Z24-P24 -> -58.3548 | AB24: =AA24+R24 -> 18.9348 | AD24: =R118+AW118 -> 0 | AE24: =AD24-AD$21 -> 0 | AF24: =AE24+AA24 -> -58.3548
B25: =Mg_HFD3!B49 -> Zn_Mg_C_HFD3_188 | C25: =(0.5-AV49)/(0.5-AV$63) -> 0.18749944 | D25: =Mg_HFD3!J49 -> 3.3636 | E25: =L49 -> 4.1986 | F25: =E25*ABS(AS49-AV49) -> 0.062865638 | G25: =E25*(ABS(MOD(AT49-AU49+2.5,1)-0.5)) -> 0.05820939 | H25: =MOD(AS49-AT49,1) -> 0.494229 | J25: =R49 -> -62.1319 | K25: =R73 -> 0 | L25: =AW73 -> 0 | M25: =K25+L25 -> 0 | O25: =J25-J$21 -> 0.0196 | P25: =K25-K$21 -> 58.3548 | Q25: =L25-L$21 -> 18.9348 | R25: =M25-M$21 -> 77.2896 | T25: =Z49 -> 12.204 | U25: =V119 -> 0 | W25: =R96-R$92 -> 0 | X25: =O25-W25 -> 0.0196 | Y25: =R25+X25 -> 77.3092 | Z25: =R165-R$161 -> 0 | AA25: =Z25-P25 -> -58.3548 | AB25: =AA25+R25 -> 18.9348 | AD25: =R119+AW119 -> 0 | AE25: =AD25-AD$21 -> 0 | AF25: =AE25+AA25 -> -58.3548
B26: =Mg_HFD3!B50 -> Zn_Mg_C_HFD3_250 | C26: =(0.5-AV50)/(0.5-AV$63) -> 0.25000226 | D26: =Mg_HFD3!J50 -> 3.359 | E26: =L50 -> 4.2173 | F26: =E26*ABS(AS50-AV50) -> 0.085682884 | G26: =E26*(ABS(MOD(AT50-AU50+2.5,1)-0.5)) -> 0.079091244 | H26: =MOD(AS50-AT50,1) -> 0.492658 | J26: =R50 -> -62.1174 | K26: =R74 -> 0 | L26: =AW74 -> 0 | M26: =K26+L26 -> 0 | O26: =J26-J$21 -> 0.0341 | P26: =K26-K$21 -> 58.3548 | Q26: =L26-L$21 -> 18.9348 | R26: =M26-M$21 -> 77.2896 | T26: =Z50 -> 12.229 | U26: =V120 -> 0 | W26: =R97-R$92 -> 0 | X26: =O26-W26 -> 0.0341 | Y26: =R26+X26 -> 77.3237 | Z26: =R166-R$161 -> 0 | AA26: =Z26-P26 -> -58.3548 | AB26: =AA26+R26 -> 18.9348 | AD26: =R120+AW120 -> 0 | AE26: =AD26-AD$21 -> 0 | AF26: =AE26+AA26 -> -58.3548
B27: =Mg_HFD3!B51 -> Zn_Mg_C_HFD3_313 | C27: =(0.5-AV51)/(0.5-AV$63) -> 0.31249605 | D27: =Mg_HFD3!J51 -> 3.3529 | E27: =L51 -> 4.2421 | F27: =E27*ABS(AS51-AV51) -> 0.11019279 | G27: =E27*(ABS(MOD(AT51-AU51+2.5,1)-0.5)) -> 0.10125044 | H27: =MOD(AS51-AT51,1) -> 0.491403 | J27: =R51 -> -62.0997 | K27: =R75 -> 0 | L27: =AW75 -> 0 | M27: =K27+L27 -> 0 | O27: =J27-J$21 -> 0.0518 | P27: =K27-K$21 -> 58.3548 | Q27: =L27-L$21 -> 18.9348 | R27: =M27-M$21 -> 77.2896 | T27: =Z51 -> 12.265 | U27: =V121 -> 0 | W27: =R98-R$92 -> 0 | X27: =O27-W27 -> 0.0518 | Y27: =R27+X27 -> 77.3414 | Z27: =R167-R$161 -> 0 | AA27: =Z27-P27 -> -58.3548 | AB27: =AA27+R27 -> 18.9348 | AD27: =R121+AW121 -> 0 | AE27: =AD27-AD$21 -> 0 | AF27: =AE27+AA27 -> -58.3548
B28: =Mg_HFD3!B52 -> Zn_Mg_C_HFD3_375 | C28: =(0.5-AV52)/(0.5-AV$63) -> 0.37499887 | D28: =Mg_HFD3!J52 -> 3.345 | E28: =L52 -> 4.274 | F28: =E28*ABS(AS52-AV52) -> 0.13775957 | G28: =E28*(ABS(MOD(AT52-AU52+2.5,1)-0.5)) -> 0.12531368 | H28: =MOD(AS52-AT52,1) -> 0.490744 | J28: =R52 -> -62.0797 | K28: =R76 -> 0 | L28: =AW76 -> 0 | M28: =K28+L28 -> 0 | O28: =J28-J$21 -> 0.0718 | P28: =K28-K$21 -> 58.3548 | Q28: =L28-L$21 -> 18.9348 | R28: =M28-M$21 -> 77.2896 | T28: =Z52 -> 12.312 | U28: =V122 -> 0 | W28: =R99-R$92 -> 0 | X28: =O28-W28 -> 0.0718 | Y28: =R28+X28 -> 77.3614 | Z28: =R168-R$161 -> 0 | AA28: =Z28-P28 -> -58.3548 | AB28: =AA28+R28 -> 18.9348 | AD28: =R122+AW122 -> 0 | AE28: =AD28-AD$21 -> 0 | AF28: =AE28+AA28 -> -58.3548
